Workbook
Name Am: #REF!
Name Am: [1]分割器计算!$B$11
Name Am: [2]分割器计算!$B$11
Name Am: [1]分割器计算!$B$11
Name Am: [2]分割器计算!$B$11
Name Am: [2]分割器计算!$B$11
Name Am: [2]分割器计算!$B$11
Name Am: [2]分割器计算!$B$11
Name Am: #REF!
Name Am: [1]分割器计算!$B$11
Name Am: #REF!
Name Am: [2]分割器计算!$B$11
Name Am: [2]分割器计算!$B$11
Name Am: [1]分割器计算!$B$11
Name Am: [2]分割器计算!$B$11
Name Am: #REF!
Name Am: [2]分割器计算!$B$11
Name Am: #REF!
Name Da: [3]擠壓螺紋下孔徑!$E$2
Name fs: #REF!
Name fs: [1]分割器计算!$B$18
Name fs: [2]分割器计算!$B$18
Name fs: [1]分割器计算!$B$18
Name fs: [2]分割器计算!$B$18
Name fs: [2]分割器计算!$B$18
Name fs: [2]分割器计算!$B$18
Name fs: [2]分割器计算!$B$18
Name fs: #REF!
Name fs: [1]分割器计算!$B$18
Name fs: #REF!
Name fs: [2]分割器计算!$B$18
Name fs: [2]分割器计算!$B$18
Name fs: [1]分割器计算!$B$18
Name fs: [2]分割器计算!$B$18
Name fs: #REF!
Name fs: [2]分割器计算!$B$18
Name fs: #REF!
Name g: 9.8
Name I_disc: #REF!
Name I_disc: [1]分割器计算!$D$5
Name I_disc: [2]分割器计算!$D$5
Name I_disc: [1]分割器计算!$D$5
Name I_disc: [2]分割器计算!$D$5
Name I_disc: [2]分割器计算!$D$5
Name I_disc: [2]分割器计算!$D$5
Name I_disc: [2]分割器计算!$D$5
Name I_disc: #REF!
Name I_disc: [1]分割器计算!$D$5
Name I_disc: #REF!
Name I_disc: [2]分割器计算!$D$5
Name I_disc: [2]分割器计算!$D$5
Name I_disc: [1]分割器计算!$D$5
Name I_disc: [2]分割器计算!$D$5
Name I_disc: #REF!
Name I_disc: [2]分割器计算!$D$5
Name I_disc: #REF!
Name I_fix: #REF!
Name I_fix: [1]分割器计算!$D$6
Name I_fix: [2]分割器计算!$D$6
Name I_fix: [1]分割器计算!$D$6

Sheet 总目录
A1: 非 标 设 计 最 强 自 动 计 算
A2: 类型 | B2: 电机选型（7） | C2: 皮带轮（8） | D2: 气动选型（7） | E2: 丝杆运动（2） | F2: 齿轮计算（7） | G2: 螺杆螺纹（8） | H2: 蜗杆计算（4）
A3: 菜单 | B3: 负载转矩计算 | C3: 皮带轮间歇运动 | D3: 气缸内径选型 | E3: 丝杠水平运动 | F3: 外啮合变位圆柱齿轮传动几何尺寸计算 | G3: 螺纹中小径计算 | H3: 圆柱蜗杆传动
B4: 惯量（惯性矩）计算 | C4: 皮带轮连续运动 | D4: 气缸推力计算 | E4: 丝杠垂直运动 | F4: 齿轮齿条 | G4: 公制/美制 粗螺纹 | H4: 圆柱蜗杆传动主要参数搭配推荐值
B5: 电机常识 | C5: 三角皮带长度计算 | D5: 气缸理论出力表 | E5: 皮带传动 | F5: 齿轮常用材料及其力学性能 | G5: 公制螺纹大全 | H5: 蜗轮传动
B6: 常用Y系列电机型号参数表 | C6: 三角皮带参数表 | D6: 真空吸盘的选型 | F6: 高度变位斜齿轮跨棒(球)距 | G6: 英制螺纹底孔对照表
B7: 电机功率确定程序 | C7: SPA、SPB带轮规格 | D7: 耗气量计算及电磁阀选择 | F7: 高变位齿轮尺寸计算 | G7: 美制特细螺纹&英制电器螺纹
B8: 伺服电机选型自动版 | C8: A型三角带规格 | D8: 真空元件的选定 | F8: 锥齿轮传动设计计算 | G8: 英制、美制管螺纹
B9: 减速机公称功率 | C9: B型三角带规格 | D9: 亚德客油压缓冲器 | F9: 齿轮齿条传动设计计算 | G9: 英制螺纹
B10: 步进电机与驱动选型 | C10: C型三角带规格 | D10: 气缸与系统选型指南 | F10: 齿轮齿条电机选型 | G10: 米制细牙螺纹
B11: 伺服电机和步进电机的区别 | D11: 气缸力计算及使用 | F11: 齿轮的换算公式 | G11: 挤压丝锥公制螺纹底孔直径
B12: 伺服电机选型 | D12: 气动元件的选型计算
A14: 类型 | B14: 单位换算（1） | C14: 带轮计算（2） | D14: 链轮&链条（5） | E14: 材料学（5） | F14: 键槽&销计算（5） | G14: 凸轮分割器选型（5） | H14: 其他公式（5）
A15: 菜单 | B15: 单位换算 | C15: 同步带轮传动设计 | D15: 链轮的基本参数 | E15: 常用工程材料属性 | F15: 外花键跨棒距 | G15: 分割器选型知识 | H15: 立柱计算
B16: 电机功率换算转矩（扭矩） | C16: 链条计算 | D16: 轴向齿廓及尺寸 | E16: 材料价格计算表 | F16: 内花键棒间距 | G16: 分度盘 | H16: 压入力计算
B17: 功率计算公式 | C17: 功率及张力计算 | D17: 链条长度计算 | E17: 常用材料硬度表 | F17: 键的强度计算 | G17: 圆盘 | H17: 弹性模量、泊松系数
B18: 所有换算单位 | C18: 张力逐点计算 | D18: 传动用短节距精密滚子链 | E18: 金属材料密度表 | F18: 销的强度计算 | G18: 间歇回转转盘运动 | H18: 焊缝及键连接受力计算比较
C19: 同步轮 | D19: 倍速链线马达功率计算 | E19: 塑料材料性能 | F19: 平键和键槽查询 | G19: 摇摆输送驱动 | H19: 稳定性系数
D20: 倍速链的张力计算 | E20: 七国铝合金牌号对照 | G20: 齿轮分割驱动 | H20: 几何体计算表
D21: 链轮齿槽形状 | E21: 七国钢材牌号对照表 | G21: 输送带式驱动 | H21: LED显示英寸计算长宽
D22: 传动用短节距精密滚子链轮参数计算表 | E22: 常用金属材料密度表 | G22: 传送带式凸轮分割器选型
E23: 常用材料力学性能 | G23: 回转圆盘式凸轮分割器选型
A25: 类型 | B25: 机械配合（4） | C25: 凸轮（5） | D25: 公差查询（4） | E25: 标准件A（4） | F25: 标准件B（5） | G25: 标准件C（2） | H25: 弹簧（2）
A26: 菜单 | B26: 转矩【扭矩】计算 | C26: 凸轮各曲线特征 | D26: 公差 | E26: 深沟球轴承规格表 | F26: 孔用弹性挡圈 | G26: 沉孔尺寸 | H26: 弹簧刚度计算大全
B27: 万向联轴器计算 | C27: 正弦加速度凸轮 | D27: 轴的基本偏差 | E27: 超越离合器设计 | F27: 轴用弹性挡圈 | G27: 塞打螺丝常用规格表 | H27: 弹簧计算
B28: 齿式联轴器计算 | C28: 正弦余弦对照表 | D28: 孔偏差 | E28: 推力球轴承尺寸表 | F28: 轴用E形扣环 | G28: UCT带滑块轴承座规格表 | H28: 压簧计算表
B29: 棘轮计算 | C29: 凸轮轮廓曲线设计 | D29: 形位公差 | E29: 圆锥滚子轴承 | F29: 扳手空间尺寸 | G29: 减速器选用方法 | H29: 氮气弹簧计算
D30: 尺寸链计算 | E30: T型槽尺寸 | F30: 紧固螺钉旋入深度及螺孔底孔深度 | G30: 超越离合器设计计算表
D31: 尺寸链知识 | F31: 常用螺栓强度极限＆屈服极限＆预紧力＆预紧力矩一览表
D32: 公差计算表
D33: 尺寸链计算表
A35: 类型 | B35: 冲压力计算 | C35: 力学性能 | D35: 力学性能2 | E35: 液压系统 | F35: 齿轮计算（7） | G35: 表面处理 | H35: 机械加工
A36: 菜单 | B36: 【理论】总冲裁力的计算 | C36: 圆 | D36: 空心正方形（圆） | E36: 液压油 | F36: 交错轴斜齿轮传动计算 | G36: 电镀余量参考 | H36: CNC钢料切削参数表
B37: 剪切力計算 | C37: 半圆环 | D37: 空心正方形 | E37: 缝隙.管路 | F37: 外啮合圆柱齿轮传动设计计算 | H37: 钢料加工参数参考表
B38: 板材压印成型之加工压力 | C38: 半圆 | D38: 六边形 | E38: 蓄能器 | F38: 外齿轮插齿、剃齿验算 | H38: CNC加工参数
B39: V型 弯曲力之计算 | C39: 带横孔圆 | D39: 三角形 | E39: 油箱.热平衡 | F39: 内齿轮插齿顶切验算 | H39: 立铣刀选用表
B40: U型 弯曲力之计算 | C40: 钢型截面 | D40: 扇形 | E40: 泵.马达 | F40: 准双曲面齿轮设计计算 | H40: 切削速度计算公式
B41: 卷料冲压效率 | C41: 花键 | D41: 扇形圆环 | E41: 油缸 | F41: 内齿轮传动计算及插齿刀验算
C42: 椭圆 | D42: 薄壁正方形 | E42: 液压冲击计算
C43: 空心椭圆 | D43: 正方形
...

Sheet 回转圆盘式凸轮分割器选型
A1: 此表为转盘式分割器选型，在输入框中输入条件（E和F列），会自动计算出负载扭矩和所需马达功率，选择分割器时动态扭矩大于此数值即可，马达同样
E2: 只需输入此列数值
A4: 图示 | D4: 输入
D5: 内容 | E5: 值 | G5: 单位 | H5: 值转换 | J5: 转换后单位 | M5: 序号 | N5: 曲线类型 | O5: 用途
D6: 1.间歇分割数 N | E6: 6 | G6: NA | H6: =E6 -> 6 | J6: NA | M6: 1 | N6: 变形台（梯）形曲线 | O6: 高速和轻负载
D7: 2.每等分回转时间∶秒 _' C Y6 w8 U) R2 K6 ? | M7: 2 | N7: 变形正弦曲线 | O7: 中高速和中度负载
D8: 3.输入轴回转数,凸轮轴速度(每分钟回转数)∶n | E8: 80 | G8: rpm | H8: =E8 -> 80 | J8: rpm | M8: 3 | N8: 变形等速度曲线 | O8: 低速和重负载
D9: 3.凸轮曲线（一般有4种）∶ | E9: 变形正弦曲线 | G9: NA | H9: =E9 -> 变形正弦曲线 | J9: NA | M9: 4 | N9: 有理式曲线 | O9: 振动控制
D10: 4.回转盘尺寸，材质∶直径D*厚度h | E10: 300 | F10: 20 | G10: mm | H10: =E10/1000 -> 0.3 | I10: =F10/1000 -> 0.02 | J10: M
E11: S45C | G11: NA | H11: =E11 -> S45C | J11: NA
D12: 5.夹具重量∶ L- u, t3 i4 c; h' _ R | E12: 3 | G12: KG/组 | H12: =E12 -> 3 | J12: KG/组
D13: 6.工件(产品)重量: | E13: 0.25 | G13: KG/组 | H13: =E13 -> 0.25 | J13: KG/组
D14: 7.转盘依靠其底部滑动面支持本身重量负荷，有效半径∶R | E14: 100 | G14: mm | H14: =E14/1000 -> 0.1 | J14: M
D15: 8.夹具固定位置（节圆直径） | E15: 200 | G15: mm | H15: =E15/1000 -> 0.2 | J15: M
D16: 9.动静比 | E16: 1 | F16: 2 | G16: NA | H16: =E16/F16 -> 0.5 | J16: NA
B18: 负载扭矩 | C18: =D45 -> 5.2083798 | D18: KG.M
B19: 马达功率 | C19: =D48*1000 -> 352.56725 | D19: W
H21: 常量 | I21: pi | J21: 3.14
A22: 计算 | B22: 内容 | C22: 公式 | D22: 计算结果 | E22: 单位 | I22: G | J22: 9.8
A23: 1 | B23: 分割数 | C23: NA | D23: =H6 -> 6 | E23: NA | I23: S45C 密度 | J23: =IF(E11="S45C",7800,2700) -> 7800 | K23: KG/M^3
A24: 2 | B24: 转位角度（驱动角）𝜃h | D24: =360*(E16/(E16+F16)) -> 120 | E24: 度 | I24: AL 密度 | J24: 2700 | K24: KG/M^3
A25: 3 | B25: 入力轴转速 | C25: NA | D25: =H8 -> 80 | E25: rpm
A26: 4 | B26: 凸轮曲线 | C26: =H9 -> 变形正弦曲线 | D26: =H9 -> 变形正弦曲线 | E26: Vm | F26: 1.76
E27: Am | F27: 5.53
E28: Qm | F28: 0.99
A29: 5 | B29: 负载扭矩：Tt
B30: 5.1 惯性扭矩：Ti
B31: a:重量
B32: 转盘重量 W1 | C32: W1=密度*体积=ρ*π*r*r*h | D32: =J23*J21*(H10/2)*(H10/2)*I10 -> 11.0214 | E32: KG
B33: 夹具重量W2 | C33: W2=夹具重量*夹具数 | D33: =H12*H6 -> 18 | E33: KG
B34: 工件重量W3 | C34: W3=夹具重量*夹具数 | D34: =H13*H6 -> 1.5 | E34: KG
B35: b:回转盘惯性扭矩
B36: 转盘惯性距I1 | D36: =D32*H10/2*H10/2/2/J22 -> 0.012652117 | E36: KG.M.S.S
B37: 夹具惯性距I2 | D37: =D33*H15/2*H15/2/J22 -> 0.018367347 | E37: KG.M.S.S
B38: 工件惯性距I3 | D38: =D34*H15/2*H15/2/J22 -> 0.0015306122 | E38: KG.M.S.S
B39: c:总惯性矩I | C39: I=I1+I2+I3 | D39: =D36+D37+D38 -> 0.032550077 | E39: KG.M.S.S
B40: d:出力轴最大角加速度：α | D40: =F27*2*J21/D23*360*E8/D24/60*360*E8/D24/60 -> 92.609067 | E40: rad/(s.s)
B41: e:静扭矩（惯性扭矩）：Ti | C41: Ti=I*α | D41: =D39*D40 -> 3.0144322 | E41: kg.m
B42: 5.2 摩擦扭矩： Tf 摩擦系数取 u=0.15 | C42: Tf=u*W*Re | D42: =(D32+D33+D34)*0.15*H15/2 -> 0.457821 | E42: kg.m
B43: 5.3 工作扭矩 Tw | C43: 在间歇分割时没有作功因此Tw=0 | D43: 0 | E43: kg.m
...

Sheet 传送带式凸轮分割器选型
A1: 传送带式凸轮分割器选型 | F1: 只需输入此列数值
A2: 凸轮分割器配合输出轴之齿轮装置应用于传动输送带，从而使输送带移动达到使用要求
A3: 图示 | D3: 输入 | M3: 序号 | N3: 曲线类型 | O3: 用途
D4: 序号 | E4: 内容 | F4: 值 | H4: 单位 | I4: 值转换 | K4: 转换后单位 | M4: 1 | N4: 变形台（梯）形曲线 | O4: 高速和轻负载
D5: 1 | E5: 输送带输送间距 Pc | F5: 239 | H5: mm | I5: =F5/10 -> 23.9 | K5: cm | M5: 2 | N5: 变形正弦曲线 | O5: 中高速和中度负载
D6: 2 | E6: 回转角度：𝜃h | F6: 120 | H6: 度 | I6: =F6 -> 120 | K6: =H6 -> 度 | M6: 3 | N6: 变形等速度曲线 | O6: 低速和重负载
D7: 3 | E7: 每行程运转时间 t | F7: 2 | H7: S/周期 | I7: =F7 -> 2 | K7: =H7 -> S/周期 | M7: 4 | N7: 有理式曲线 | O7: 振动控制
D8: 5 | E8: 凸轮曲线∶ | F8: 变形正弦曲线 | H8: NA | I8: =F8 -> 变形正弦曲线 | K8: NA
D9: 6 | E9: 主齿轮A 质量 W1 | F9: 8 | H9: KG | I9: =F9 -> 8 | K9: =H9 -> KG | M9: 常量 | N9: pi | O9: 3.14
D10: 7 | E10: 主齿轮A 节圆直径D1 | F10: 180 | H10: mm | I10: =F10/10 -> 18 | K10: cm | N10: G | O10: 9.8 | P10: =O10*100 -> 980
D11: 8 | E11: 从动齿轮B 质量 W2 | F11: 5 | H11: KG | I11: =F11 -> 5 | K11: =H11 -> KG | N11: S45C 密度 | O11: 7800 | P11: KG/M^3
D12: 9 | E12: 从动齿轮B 节圆直径D2 | F12: 100 | H12: mm | I12: =F12/10 -> 10 | K12: cm | N12: AL 密度 | O12: 2700 | P12: KG/M^3
D13: 10 | E13: 传动轴质量 W3 | F13: 4 | H13: KG/支 | I13: =F13 -> 4 | K13: =H13 -> KG/支
D14: 11 | E14: 传动轴数量 N3 | F14: 2 | H14: 支 | I14: =F14 -> 2 | K14: =H14 -> 支
D15: 12 | E15: 传动轴直径 | F15: 50 | H15: mm | I15: =F15/10 -> 5 | K15: cm
D16: 13 | E16: 链轮质量 W4 | F16: 5 | H16: KG/组 | I16: =F16 -> 5 | K16: =H16 -> KG/组
D17: 14 | E17: 链轮组数 N4 | F17: 4 | H17: 组 | I17: =F17 -> 4 | K17: =H17 -> 组
D18: 15 | E18: 链轮节圆直径 Dc | F18: 254 | H18: mm | I18: =F18/10 -> 25.4 | K18: cm
D19: 16 | E19: 链条质量 W5 | F19: 10 | H19: KG/组 | I19: =F19 -> 10 | K19: =H19 -> KG/组
D20: 17 | E20: 链条组数 N5 | F20: 2 | H20: 组 | I20: =F20 -> 2 | K20: =H20 -> 组
D21: 18 | E21: 夹具质量 W6 | F21: 0.7 | H21: KG/组 | I21: =F21 -> 0.7 | K21: =H21 -> KG/组
D22: 19 | E22: 夹具组数 N6 | F22: 20 | H22: 组 | I22: =F22 -> 20 | K22: =H22 -> 组
D23: 20 | E23: 工件质量 W7 | F23: 1 | H23: KG/组 | I23: =F23 -> 1 | K23: =H23 -> KG/组
D24: 21 | E24: 工件组数 | F24: 4 | H24: 组 | I24: =F24 -> 4 | K24: =H24 -> 组
D25: 22 | E25: 速度比 ：𝛾 | F25: =F10/F12 -> 1.8 | H25: NA | I25: =F25 -> 1.8 | K25: =H25 -> NA
E26: 输送带摩擦系数 | F26: 0.15
B27: 负载扭矩 | C27: =D57 -> 7.6878542 | D27: KG.M
B28: 马达功率 | C28: =D61*1000 -> 194.93464 | D28: W
A30: 计算 | B30: 内容 | C30: 公式 | D30: 计算结果 | E30: 单位
A31: 1 | B31: 定位等分（分割数）N | D31: =O9*F18*F25/F5 -> 6.006728 | E31: NA
A32: 2 | B32: 输入轴转速 | C32: n=60/t | D32: =60/I7 -> 30 | E32: rpm
A33: 3 | B33: 凸轮曲线 | C33: =I8 -> 变形正弦曲线 | D33: Vm | E33: 1.76
D34: Am | E34: 5.53
D35: Qm | E35: 0.99
A36: 4 | B36: 负载扭矩： Tt
A37: 4.1 | B37: 静扭矩（惯性扭矩）：Ti
B38: a:主动齿轮重量∶W1=8kg 节圆直径=φ180 那么主动齿轮惯性矩∶ | D38: =I9*I10/2*I10/2/2/P10 -> 0.33061224 | E38: kg,cm,s,s
B39: b:输送带惯性矩：
B40: ① 从动齿轮惯性距：I2 | D40: =I11*(I12/2*I12/2+I15/2*I15/2)/2/P10 -> 0.079719388 | E40: kg,cm,s,s
B41: ② 传动轴之惯性矩∶I3 | D41: =I13*I15/2*I15/2/2/P10*I14 -> 0.025510204 | E41: kg,cm,s,s
...

Sheet 切削速度计算公式
A1: 车削速度计算（公众号：曼仑）
A2: YT15 | C2: Cv | D2: t(min) | E2: ap(mm) | F2: f(mm/r) | G2: V(m/min) | H2: v(r/min) | I2: D(mm)
B3: F≤0.3 | C3: 356 | D3: 180 | E3: 0.7 | F3: 0.3 | G3: =C3/(D3^0.2)/(E3^0.15)/(F3^0.2) -> 169.12451 | H3: =1000*G3/(3.142*I3) -> 522.59245 | I3: 103
B5: F≤0.75 | C5: 296 | D5: 240 | E5: 0.3 | F5: 0.7 | G5: =C5/(D5^0.2)/(E5^0.15)/(F5^0.35) -> 134.24464 | H5: =1000*G5/(3.142*I5) -> 414.81414 | I5: 103
B7: F＞0.75 | C7: 288 | D7: 240 | E7: 2.5 | F7: 0.75 | G7: =C7/(D7^0.2)/(E7^0.15)/(F7^0.45) -> 95.473242 | H7: =1000*G7/(3.142*I7) -> 296.73962 | I7: 102.4
A9: YG6 | B9: F>0.4 | C9: 292 | D9: 240 | E9: 2.5 | F9: 0.6 | G9: =C9/(D9^0.2)/(E9^0.15)/(F9^0.4) -> 104.32517 | H9: =1000*G9/(3.142*I9) -> 335.38816 | I9: 99
B10: F<0.4 | C10: 243 | D10: 240 | E10: 1.3 | F10: 0.3 | G10: =C10/(D10^0.2)/(E10^0.15)/(F10^0.4) -> 126.36419 | H10: =1000*G10/(3.142*I10) -> 395.84406 | I10: 101.6
A12: W18Cr4V | C12: 35 | E12: 3 | F12: 0.4 | G12: =C12/(E12^0.15)/(F12^0.4) -> 42.822879 | H12: =1000*G12/(3.142*I12) -> 168.67795 | I12: 80.8
A14: 铣削速度计算
A16: YG8(HB180) | B16: d(mm) | C16: Cv | D16: t(min) | E16: ap(mm) | F16: fz(mm/r) | G16: ae(mm) | H16: z | I16: V(m/min) | J16: v(r/min)
B17: 250 | D17: 300 | E17: 3 | F17: 0.08 | G17: 112 | H17: 16 | I17: =(89.4*B17^0.2)/(D17^0.15)/(E17^0.5)/(F17^0.4)/(G17^0.1)/(H17^0.1) -> 85.946246 | J17: =1000*I17/(3.14*B17) -> 109.48566
A18: 盘铣刀 | B18: 250 | C18: 55 | D18: 300 | E18: 3 | F18: 0.18 | G18: 112 | H18: 16 | I18: =(89.4*B18^0.25)/(D18^0.2)/(E18^0.3)/(F18^0.34)/(G18^0.1)/(H18^0.1) -> 69.204676 | J18: =1000*I18/(3.14*B18) -> 88.158823
A19: 立铣刀 | B19: 12 | D19: 120 | E19: 5.2 | F19: 0.03 | G19: 12 | H19: 3 | I19: =(75.5*B19^0.7)/(D19^0.25)/(E19^0.5)/(F19^0.2)/(G19^0.3)/(H19^0.3) -> 39.197813 | J19: =1000*I19/(3.14*B19) -> 1040.2817
A20: 套式面铣刀 | B20: 50 | D20: 180 | E20: 9.5 | F20: 0.12 | G20: 50 | H20: 3 | I20: =(382*B20^0.2)/(D20^0.2)/(E20^0.1)/(F20^0.4)/(G20^0.2) -> 252.09487 | J20: =1000*I20/(3.14*B20) -> 1605.6998
A21: 钻削速度计算
A22: W18Cr4V | C22: d(mm) | D22: t(min) | E22: f(mm/r) | F22: V(m/min) | G22: v(r/min) | H22: ap(mm)
B23: f<0.3mm/r | C23: 10.7 | D23: 300 | E23: 0.15 | F23: =14.2*C23^0.25/(D23^0.125)/(E23^0.55) -> 35.739127 | G23: =1000*F23/(3.14*C23) -> 1063.7278 | H23: 17.4
B24: f>0.3mm/r | C24: 18.5 | D24: 240 | E24: 0.315 | F24: =16.5*C24^0.25/(D24^0.125)/(E24^0.4) -> 27.379546 | G24: =1000*F24/(3.14*C24) -> 471.32977
B25: 扩孔 | C25: 14.3 | D25: 120 | E25: 0.5 | F25: =20.6*C25^0.6/(D25^0.25)/(H25^0.2)/(E25^0.5) -> 23.299791 | G25: =1000*F25/(3.14*C25) -> 518.90319 | H25: 22.5
B26: 铰孔 | C26: 15 | D26: 240 | E26: 0.2 | F26: =12.1*C26^0.3/(D26^0.4)/(H26^0.2)/(E26^0.65) -> 7.5448873 | G26: =1000*F26/(3.14*C26) -> 160.18869 | H26: 2
A28: 螺纹加工
C30: p(mm) | D30: d0(mm) | E30: Cv | F30: t(min) | G30: x | H30: m | I30: y | J30: V(m/min) | K30: v(r/min)
C31: 1.25 | D31: 8 | E31: 6.2 | F31: 30 | G31: 1.2 | H31: 0.6 | I31: 0.9 | J31: =E31*D31^G31/(F31^H31)/(C31^I31) -> 7.9911247 | K31: =1000*J31/(3.14*D31) -> 318.11802
D33: 102 | J33: 25 | K33: 22500
A35: 磨削切前用量的计算公式
C36: d | D36: v | E36: fB | F36: K1 | G36: K2 | H36: ft | I36: K3
A37: 外圆磨 | B37: 粗磨圆柱表面的横进给量 | C37: 101.6 | D37: 45 | E37: 25.2 | F37: 0.8 | G37: 1 | H37: =(0.044*C37^0.3*F37*G37)/D37/E37 -> 0.00012416458
B38: 精磨圆柱表面的横进给量 | H38: =(0.4*C38^0.5*F38*G38)/D38/E38 -> #DIV/0!
A39: 内圆磨 | B39: 粗磨内圆的横进给量 | H39: =(0.002*C39*F39*G39*I39)/D39/E39 -> #DIV/0!
B40: 粗磨内圆的横进给量 | C40: 22.2 | D40: 25 | E40: 10 | F40: 0.8 | G40: 1 | H40: =(0.067*C40^0.9*F40*G40*I40)/D40/E40 -> 0.0023389302 | I40: 0.67 | J40: D>12
H41: =(0.0104*C41^1.57*F41*G41*I41)/D41/E41 -> #DIV/0! | J41: D=10-12
A43: 滚齿、花键加工
A44: 钢 | B44: m=7-26 | C44: t | D44: f | E44: m | F44: V
C45: 960 | D45: 2.2 | E45: 8 | F45: =350/(C45^0.33)/(D45^0.5)/(E45^0.1) -> 19.879168 | G45: =1000*F45/(3.14*110) -> 57.554047

Sheet 立铣刀选用表
A1: 切速 | B1: 应用 | C1: ISO | D1: 材料 | E1: 操作 | F1: 优先级 | G1: 型号 | H1: 图形
A2: 范围 | B2: 场合 | C2: 分组 | E2: 方式
A3: 常规 | B3: 铣槽 | C3: P | D3: 钢HRC<=38 | E3: M | F3: 首选 | G3: 5501R302GM
A4: 常规 | B4: 铣槽 | C4: P | D4: 钢HRC<=38 | E4: M | F4: 首选 | G4: 5601R302GM
A5: 常规 | B5: 铣槽 | C5: P | D5: 钢HRC<=38 | E5: M | F5: 首选 | G5: 5502R302GM
A6: 常规 | B6: 铣槽 | C6: P | D6: 钢HRC<=38 | E6: M | F6: 首选 | G6: 5602R302GM
A7: 常规 | B7: 铣槽 | C7: P | D7: 钢HRC<=38 | E7: M | F7: 首选 | G7: 5108R302GM
A8: 常规 | B8: 铣槽 | C8: P | D8: 钢HRC<=38 | E8: R | F8: 首选 | G8: 5602R404GR
A9: 常规 | B9: 铣槽 | C9: P | D9: 钢HRC<=38 | E9: M | F9: 备选 | G9: 5501R303GM
A10: 常规 | B10: 铣槽 | C10: P | D10: 钢HRC<=38 | E10: M | F10: 备选 | G10: 5601R303GM
A11: 常规 | B11: 铣槽 | C11: P | D11: 钢HRC<=38 | E11: M | F11: 备选 | G11: 5502R303GM
A12: 常规 | B12: 铣槽 | C12: P | D12: 钢HRC<=38 | E12: M | F12: 备选 | G12: 5602R303GM
A13: 常规 | B13: 铣槽 | C13: P | D13: 钢HRC<=38 | E13: M | F13: 备选 | G13: 5108R303GM
A14: 常规 | B14: 铣槽 | C14: M | D14: 不锈钢 | E14: M | F14: 首选 | G14: 5501R302GM
... A149: 高速切削 | B149: 仿形铣削 | C149: H | D149: 淬硬钢材 | E149: H | F149: 备选 | G149: 5566R302GH

Sheet 常用螺栓强度极限＆屈服极限＆预紧力＆预紧力矩一览表
A1: 常用螺栓强度极限/屈服极限/预紧力/预紧力矩一览表（公众号：曼仑）
A2: 螺 栓 规 格 | B2: 螺栓型号 | C2: 螺栓公称直径D/MM | D2: 应力截面积/MM² | E2: 性能等级
E3: 3.6 | I3: 4.6 | M3: 4.8 | Q3: 5.6 | U3: 5.8 | Y3: 6.8 | AC3: 8.8 | AG3: 9.8 | AK3: 10.9 | AO3: 12.9
E4: 强度极限/N | F4: 屈服极限/N | G4: 预紧力/N | H4: 预紧力矩/N.M | I4: 强度极限/N | J4: 屈服极限/N | K4: 预紧力/N | L4: 预紧力矩/N.M | M4: 强度极限/N | N4: 屈服极限/N | O4: 预紧力/N | P4: 预紧力矩/N.M | Q4: 强度极限/N | R4: 屈服极限/N | S4: 预紧力/N | T4: 预紧力矩/N.M | U4: 强度极限/N | V4: 屈服极限/N | W4: 预紧力/N | X4: 预紧力矩/N.M | Y4: 强度极限/N | Z4: 屈服极限/N | AA4: 预紧力/N | AB4: 预紧力矩/N.M | AC4: 强度极限/N | AD4: 屈服极限/N | AE4: 预紧力/N | AF4: 预紧力矩/N.M | AG4: 强度极限/N | AH4: 屈服极限/N | AI4: 预紧力/N | AJ4: 预紧力矩/N.M | AK4: 强度极限/N | AL4: 屈服极限/N | AM4: 预紧力/N | AN4: 预紧力矩/N.M | AO4: 强度极限/N | AP4: 屈服极限/N | AQ4: 预紧力/N | AR4: 预紧力矩/N.M
B5: M1 | C5: 1 | D5: 0.46 | E5: =D5*300 -> 138 | F5: =D5*180 -> 82.8 | G5: =0.6*180*D5 -> 49.68 | H5: =G30*G5*C5*0.001 -> 0.014904 | I5: =D5*400 -> 184 | J5: =D5*240 -> 110.4 | K5: =J5*0.6 -> 66.24 | L5: =G30*K5*C5*0.001 -> 0.019872 | M5: =D5*400 -> 184 | N5: =D5*320 -> 147.2 | O5: =N5*0.6 -> 88.32 | P5: =G30*O5*C5*0.001 -> 0.026496 | Q5: =D5*500 -> 230 | R5: =D5*300 -> 138 | S5: =R5*0.6 -> 82.8 | T5: =G30*S5*C5*0.001 -> 0.02484 | U5: =D5*500 -> 230 | V5: =D5*400 -> 184 | W5: =V5*0.6 -> 110.4 | X5: =G30*C5*W5*0.001 -> 0.03312 | Y5: =D5*600 -> 276 | Z5: =D5*480 -> 220.8 | AA5: =Z5*0.6 -> 132.48 | AB5: =G30*C5*AA5*0.001 -> 0.039744 | AC5: =D5*800 -> 368 | AD5: =D5*640 -> 294.4 | AE5: =AD5*0.6 -> 176.64 | AF5: =G30*C5*AE5*0.001 -> 0.052992 | AG5: =D5*900 -> 414 | AH5: =D5*720 -> 331.2 | AI5: =AH5*0.6 -> 198.72 | AJ5: =G30*C5*AI5*0.001 -> 0.059616 | AK5: =D5*1000 -> 460 | AL5: =D5*900 -> 414 | AM5: =AL5*0.6 -> 248.4 | AN5: =G30*C5*AM5*0.001 -> 0.07452 | AO5: =D5*1200 -> 552 | AP5: =D5*1080 -> 496.8 | AQ5: =AP5*0.6 -> 298.08 | AR5: =G30*C5*AQ5*0.001 -> 0.089424
B6: M2 | C6: 2 | D6: 2.07 | E6: =D6*300 -> 621 | F6: =D6*180 -> 372.6 | G6: =0.6*180*D6 -> 223.56 | H6: =G30*G6*C6*0.001 -> 0.134136 | I6: =D6*400 -> 828 | J6: =D6*240 -> 496.8 | K6: =J6*0.6 -> 298.08 | L6: =G30*K6*C6*0.001 -> 0.178848 | M6: =D6*400 -> 828 | N6: =D6*320 -> 662.4 | O6: =N6*0.6 -> 397.44 | P6: =G30*O6*C6*0.001 -> 0.238464 | Q6: =D6*500 -> 1035 | R6: =D6*300 -> 621 | S6: =R6*0.6 -> 372.6 | T6: =G30*S6*C6*0.001 -> 0.22356 | U6: =D6*500 -> 1035 | V6: =D6*400 -> 828 | W6: =V6*0.6 -> 496.8 | X6: =G30*C6*W6*0.001 -> 0.29808 | Y6: =D6*600 -> 1242 | Z6: =D6*480 -> 993.6 | AA6: =Z6*0.6 -> 596.16 | AB6: =G30*C6*AA6*0.001 -> 0.357696 | AC6: =D6*800 -> 1656 | AD6: =D6*640 -> 1324.8 | AE6: =AD6*0.6 -> 794.88 | AF6: =G30*C6*AE6*0.001 -> 0.476928 | AG6: =D6*900 -> 1863 | AH6: =D6*720 -> 1490.4 | AI6: =AH6*0.6 -> 894.24 | AJ6: =G30*C6*AI6*0.001 -> 0.536544 | AK6: =D6*1000 -> 2070 | AL6: =D6*900 -> 1863 | AM6: =AL6*0.6 -> 1117.8 | AN6: =G30*C6*AM6*0.001 -> 0.67068 | AO6: =D6*1200 -> 2484 | AP6: =D6*1080 -> 2235.6 | AQ6: =AP6*0.6 -> 1341.36 | AR6: =G30*C6*AQ6*0.001 -> 0.804816
B7: M3 | C7: 3 | D7: 5.03 | E7: =D7*300 -> 1509 | F7: =D7*180 -> 905.4 | G7: =0.6*180*D7 -> 543.24 | H7: =G30*G7*C7*0.001 -> 0.488916 | I7: =D7*400 -> 2012 | J7: =D7*240 -> 1207.2 | K7: =J7*0.6 -> 724.32 | L7: =G30*K7*C7*0.001 -> 0.651888 | M7: =D7*400 -> 2012 | N7: =D7*320 -> 1609.6 | O7: =N7*0.6 -> 965.76 | P7: =G30*O7*C7*0.001 -> 0.869184 | Q7: =D7*500 -> 2515 | R7: =D7*300 -> 1509 | S7: =R7*0.6 -> 905.4 | T7: =G30*S7*C7*0.001 -> 0.81486 | U7: =D7*500 -> 2515 | V7: =D7*400 -> 2012 | W7: =V7*0.6 -> 1207.2 | X7: =G30*C7*W7*0.001 -> 1.08648 | Y7: =D7*600 -> 3018 | Z7: =D7*480 -> 2414.4 | AA7: =Z7*0.6 -> 1448.64 | AB7: =G30*C7*AA7*0.001 -> 1.303776 | AC7: =D7*800 -> 4024 | AD7: =D7*640 -> 3219.2 | AE7: =AD7*0.6 -> 1931.52 | AF7: =G30*C7*AE7*0.001 -> 1.738368 | AG7: =D7*900 -> 4527 | AH7: =D7*720 -> 3621.6 | AI7: =AH7*0.6 -> 2172.96 | AJ7: =G30*C7*AI7*0.001 -> 1.955664 | AK7: =D7*1000 -> 5030 | AL7: =D7*900 -> 4527 | AM7: =AL7*0.6 -> 2716.2 | AN7: =G30*C7*AM7*0.001 -> 2.44458 | AO7: =D7*1200 -> 6036 | AP7: =D7*1080 -> 5432.4 | AQ7: =AP7*0.6 -> 3259.44 | AR7: =G30*C7*AQ7*0.001 -> 2.933496
B8: M4 | C8: 4 | D8: 8.78 | E8: =D8*300 -> 2634 | F8: =D8*180 -> 1580.4 | G8: =0.6*180*D8 -> 948.24 | H8: =G30*G8*C8*0.001 -> 1.137888 | I8: =D8*400 -> 3512 | J8: =D8*240 -> 2107.2 | K8: =J8*0.6 -> 1264.32 | L8: =G30*K8*C8*0.001 -> 1.517184 | M8: =D8*400 -> 3512 | N8: =D8*320 -> 2809.6 | O8: =N8*0.6 -> 1685.76 | P8: =G30*O8*C8*0.001 -> 2.022912 | Q8: =D8*500 -> 4390 | R8: =D8*300 -> 2634 | S8: =R8*0.6 -> 1580.4 | T8: =G30*S8*C8*0.001 -> 1.89648 | U8: =D8*500 -> 4390 | V8: =D8*400 -> 3512 | W8: =V8*0.6 -> 2107.2 | X8: =G30*C8*W8*0.001 -> 2.52864 | Y8: =D8*600 -> 5268 | Z8: =D8*480 -> 4214.4 | AA8: =Z8*0.6 -> 2528.64 | AB8: =G30*C8*AA8*0.001 -> 3.034368 | AC8: =D8*800 -> 7024 | AD8: =D8*640 -> 5619.2 | AE8: =AD8*0.6 -> 3371.52 | AF8: =G30*C8*AE8*0.001 -> 4.045824 | AG8: =D8*900 -> 7902 | AH8: =D8*720 -> 6321.6 | AI8: =AH8*0.6 -> 3792.96 | AJ8: =G30*C8*AI8*0.001 -> 4.551552 | AK8: =D8*1000 -> 8780 | AL8: =D8*900 -> 7902 | AM8: =AL8*0.6 -> 4741.2 | AN8: =G30*C8*AM8*0.001 -> 5.68944 | AO8: =D8*1200 -> 10536 | AP8: =D8*1080 -> 9482.4 | AQ8: =AP8*0.6 -> 5689.44 | AR8: =G30*C8*AQ8*0.001 -> 6.827328
B9: M5 | C9: 5 | D9: 14.2 | E9: =D9*300 -> 4260 | F9: =D9*180 -> 2556 | G9: =0.6*180*D9 -> 1533.6 | H9: =G30*G9*C9*0.001 -> 2.3004 | I9: =D9*400 -> 5680 | J9: =D9*240 -> 3408 | K9: =J9*0.6 -> 2044.8 | L9: =G30*K9*C9*0.001 -> 3.0672 | M9: =D9*400 -> 5680 | N9: =D9*320 -> 4544 | O9: =N9*0.6 -> 2726.4 | P9: =G30*O9*C9*0.001 -> 4.0896 | Q9: =D9*500 -> 7100 | R9: =D9*300 -> 4260 | S9: =R9*0.6 -> 2556 | T9: =G30*S9*C9*0.001 -> 3.834 | U9: =D9*500 -> 7100 | V9: =D9*400 -> 5680 | W9: =V9*0.6 -> 3408 | X9: =G30*C9*W9*0.001 -> 5.112 | Y9: =D9*600 -> 8520 | Z9: =D9*480 -> 6816 | AA9: =Z9*0.6 -> 4089.6 | AB9: =G30*C9*AA9*0.001 -> 6.1344 | AC9: =D9*800 -> 11360 | AD9: =D9*640 -> 9088 | AE9: =AD9*0.6 -> 5452.8 | AF9: =G30*C9*AE9*0.001 -> 8.1792 | AG9: =D9*900 -> 12780 | AH9: =D9*720 -> 10224 | AI9: =AH9*0.6 -> 6134.4 | AJ9: =G30*C9*AI9*0.001 -> 9.2016 | AK9: =D9*1000 -> 14200 | AL9: =D9*900 -> 12780 | AM9: =AL9*0.6 -> 7668 | AN9: =G30*C9*AM9*0.001 -> 11.502 | AO9: =D9*1200 -> 17040 | AP9: =D9*1080 -> 15336 | AQ9: =AP9*0.6 -> 9201.6 | AR9: =G30*C9*AQ9*0.001 -> 13.8024
B10: M6 | C10: 6 | D10: 20.1 | E10: =D10*300 -> 6030 | F10: =D10*180 -> 3618 | G10: =0.6*180*D10 -> 2170.8 | H10: =G30*G10*C10*0.001 -> 3.90744 | I10: =D10*400 -> 8040 | J10: =D10*240 -> 4824 | K10: =J10*0.6 -> 2894.4 | L10: =G30*K10*C10*0.001 -> 5.20992 | M10: =D10*400 -> 8040 | N10: =D10*320 -> 6432 | O10: =N10*0.6 -> 3859.2 | P10: =G30*O10*C10*0.001 -> 6.94656 | Q10: =D10*500 -> 10050 | R10: =D10*300 -> 6030 | S10: =R10*0.6 -> 3618 | T10: =G30*S10*C10*0.001 -> 6.5124 | U10: =D10*500 -> 10050 | V10: =D10*400 -> 8040 | W10: =V10*0.6 -> 4824 | X10: =G30*C10*W10*0.001 -> 8.6832 | Y10: =D10*600 -> 12060 | Z10: =D10*480 -> 9648 | AA10: =Z10*0.6 -> 5788.8 | AB10: =G30*C10*AA10*0.001 -> 10.41984 | AC10: =D10*800 -> 16080 | AD10: =D10*640 -> 12864 | AE10: =AD10*0.6 -> 7718.4 | AF10: =G30*C10*AE10*0.001 -> 13.89312 | AG10: =D10*900 -> 18090 | AH10: =D10*720 -> 14472 | AI10: =AH10*0.6 -> 8683.2 | AJ10: =G30*C10*AI10*0.001 -> 15.62976 | AK10: =D10*1000 -> 20100 | AL10: =D10*900 -> 18090 | AM10: =AL10*0.6 -> 10854 | AN10: =G30*C10*AM10*0.001 -> 19.5372 | AO10: =D10*1200 -> 24120 | AP10: =D10*1080 -> 21708 | AQ10: =AP10*0.6 -> 13024.8 | AR10: =G30*C10*AQ10*0.001 -> 23.44464
B11: M8 | C11: 8 | D11: 36.6 | E11: =D11*300 -> 10980 | F11: =D11*180 -> 6588 | G11: =0.6*180*D11 -> 3952.8 | H11: =G30*G11*C11*0.001 -> 9.48672 | I11: =D11*400 -> 14640 | J11: =D11*240 -> 8784 | K11: =J11*0.6 -> 5270.4 | L11: =G30*K11*C11*0.001 -> 12.64896 | M11: =D11*400 -> 14640 | N11: =D11*320 -> 11712 | O11: =N11*0.6 -> 7027.2 | P11: =G30*O11*C11*0.001 -> 16.86528 | Q11: =D11*500 -> 18300 | R11: =D11*300 -> 10980 | S11: =R11*0.6 -> 6588 | T11: =G30*S11*C11*0.001 -> 15.8112 | U11: =D11*500 -> 18300 | V11: =D11*400 -> 14640 | W11: =V11*0.6 -> 8784 | X11: =G30*C11*W11*0.001 -> 21.0816 | Y11: =D11*600 -> 21960 | Z11: =D11*480 -> 17568 | AA11: =Z11*0.6 -> 10540.8 | AB11: =G30*C11*AA11*0.001 -> 25.29792 | AC11: =D11*800 -> 29280 | AD11: =D11*640 -> 23424 | AE11: =AD11*0.6 -> 14054.4 | AF11: =G30*C11*AE11*0.001 -> 33.73056 | AG11: =D11*900 -> 32940 | AH11: =D11*720 -> 26352 | AI11: =AH11*0.6 -> 15811.2 | AJ11: =G30*C11*AI11*0.001 -> 37.94688 | AK11: =D11*1000 -> 36600 | AL11: =D11*900 -> 32940 | AM11: =AL11*0.6 -> 19764 | AN11: =G30*C11*AM11*0.001 -> 47.4336 | AO11: =D11*1200 -> 43920 | AP11: =D11*1080 -> 39528 | AQ11: =AP11*0.6 -> 23716.8 | AR11: =G30*C11*AQ11*0.001 -> 56.92032
B12: M10 | C12: 10 | D12: 58 | E12: =D12*300 -> 17400 | F12: =D12*180 -> 10440 | G12: =0.6*180*D12 -> 6264 | H12: =G30*G12*C12*0.001 -> 18.792 | I12: =D12*400 -> 23200 | J12: =D12*240 -> 13920 | K12: =J12*0.6 -> 8352 | L12: =G30*K12*C12*0.001 -> 25.056 | M12: =D12*400 -> 23200 | N12: =D12*320 -> 18560 | O12: =N12*0.6 -> 11136 | P12: =G30*O12*C12*0.001 -> 33.408 | Q12: =D12*500 -> 29000 | R12: =D12*300 -> 17400 | S12: =R12*0.6 -> 10440 | T12: =G30*S12*C12*0.001 -> 31.32 | U12: =D12*500 -> 29000 | V12: =D12*400 -> 23200 | W12: =V12*0.6 -> 13920 | X12: =G30*C12*W12*0.001 -> 41.76 | Y12: =D12*600 -> 34800 | Z12: =D12*480 -> 27840 | AA12: =Z12*0.6 -> 16704 | AB12: =G30*C12*AA12*0.001 -> 50.112 | AC12: =D12*800 -> 46400 | AD12: =D12*640 -> 37120 | AE12: =AD12*0.6 -> 22272 | AF12: =G30*C12*AE12*0.001 -> 66.816 | AG12: =D12*900 -> 52200 | AH12: =D12*720 -> 41760 | AI12: =AH12*0.6 -> 25056 | AJ12: =G30*C12*AI12*0.001 -> 75.168 | AK12: =D12*1000 -> 58000 | AL12: =D12*900 -> 52200 | AM12: =AL12*0.6 -> 31320 | AN12: =G30*C12*AM12*0.001 -> 93.96 | AO12: =D12*1200 -> 69600 | AP12: =D12*1080 -> 62640 | AQ12: =AP12*0.6 -> 37584 | AR12: =G30*C12*AQ12*0.001 -> 112.752
B13: M12 | C13: 12 | D13: 84.3 | E13: =D13*300 -> 25290 | F13: =D13*180 -> 15174 | G13: =0.6*180*D13 -> 9104.4 | H13: =G30*G13*C13*0.001 -> 32.77584 | I13: =D13*400 -> 33720 | J13: =D13*240 -> 20232 | K13: =J13*0.6 -> 12139.2 | L13: =G30*K13*C13*0.001 -> 43.70112 | M13: =D13*400 -> 33720 | N13: =D13*320 -> 26976 | O13: =N13*0.6 -> 16185.6 | P13: =G30*O13*C13*0.001 -> 58.26816 | Q13: =D13*500 -> 42150 | R13: =D13*300 -> 25290 | S13: =R13*0.6 -> 15174 | T13: =G30*S13*C13*0.001 -> 54.6264 | U13: =D13*500 -> 42150 | V13: =D13*400 -> 33720 | W13: =V13*0.6 -> 20232 | X13: =G30*C13*W13*0.001 -> 72.8352 | Y13: =D13*600 -> 50580 | Z13: =D13*480 -> 40464 | AA13: =Z13*0.6 -> 24278.4 | AB13: =G30*C13*AA13*0.001 -> 87.40224 | AC13: =D13*800 -> 67440 | AD13: =D13*640 -> 53952 | AE13: =AD13*0.6 -> 32371.2 | AF13: =G30*C13*AE13*0.001 -> 116.53632 | AG13: =D13*900 -> 75870 | AH13: =D13*720 -> 60696 | AI13: =AH13*0.6 -> 36417.6 | AJ13: =G30*C13*AI13*0.001 -> 131.10336 | AK13: =D13*1000 -> 84300 | AL13: =D13*900 -> 75870 | AM13: =AL13*0.6 -> 45522 | AN13: =G30*C13*AM13*0.001 -> 163.8792 | AO13: =D13*1200 -> 101160 | AP13: =D13*1080 -> 91044 | AQ13: =AP13*0.6 -> 54626.4 | AR13: =G30*C13*AQ13*0.001 -> 196.65504
B14: M14 | C14: 14 | D14: 115 | E14: =D14*300 -> 34500 | F14: =D14*180 -> 20700 | G14: =0.6*180*D14 -> 12420 | H14: =G30*G14*C14*0.001 -> 52.164 | I14: =D14*400 -> 46000 | J14: =D14*240 -> 27600 | K14: =J14*0.6 -> 16560 | L14: =G30*K14*C14*0.001 -> 69.552 | M14: =D14*400 -> 46000 | N14: =D14*320 -> 36800 | O14: =N14*0.6 -> 22080 | P14: =G30*O14*C14*0.001 -> 92.736 | Q14: =D14*500 -> 57500 | R14: =D14*300 -> 34500 | S14: =R14*0.6 -> 20700 | T14: =G30*S14*C14*0.001 -> 86.94 | U14: =D14*500 -> 57500 | V14: =D14*400 -> 46000 | W14: =V14*0.6 -> 27600 | X14: =G30*C14*W14*0.001 -> 115.92 | Y14: =D14*600 -> 69000 | Z14: =D14*480 -> 55200 | AA14: =Z14*0.6 -> 33120 | AB14: =G30*C14*AA14*0.001 -> 139.104 | AC14: =D14*800 -> 92000 | AD14: =D14*640 -> 73600 | AE14: =AD14*0.6 -> 44160 | AF14: =G30*C14*AE14*0.001 -> 185.472 | AG14: =D14*900 -> 103500 | AH14: =D14*720 -> 82800 | AI14: =AH14*0.6 -> 49680 | AJ14: =G30*C14*AI14*0.001 -> 208.656 | AK14: =D14*1000 -> 115000 | AL14: =D14*900 -> 103500 | AM14: =AL14*0.6 -> 62100 | AN14: =G30*C14*AM14*0.001 -> 260.82 | AO14: =D14*1200 -> 138000 | AP14: =D14*1080 -> 124200 | AQ14: =AP14*0.6 -> 74520 | AR14: =G30*C14*AQ14*0.001 -> 312.984
B15: M16 | C15: 16 | D15: 157 | E15: =D15*300 -> 47100 | F15: =D15*180 -> 28260 | G15: =0.6*180*D15 -> 16956 | H15: =G30*G15*C15*0.001 -> 81.3888 | I15: =D15*400 -> 62800 | J15: =D15*240 -> 37680 | K15: =J15*0.6 -> 22608 | L15: =G30*K15*C15*0.001 -> 108.5184 | M15: =D15*400 -> 62800 | N15: =D15*320 -> 50240 | O15: =N15*0.6 -> 30144 | P15: =G30*O15*C15*0.001 -> 144.6912 | Q15: =D15*500 -> 78500 | R15: =D15*300 -> 47100 | S15: =R15*0.6 -> 28260 | T15: =G30*S15*C15*0.001 -> 135.648 | U15: =D15*500 -> 78500 | V15: =D15*400 -> 62800 | W15: =V15*0.6 -> 37680 | X15: =G30*C15*W15*0.001 -> 180.864 | Y15: =D15*600 -> 94200 | Z15: =D15*480 -> 75360 | AA15: =Z15*0.6 -> 45216 | AB15: =G30*C15*AA15*0.001 -> 217.0368 | AC15: =D15*800 -> 125600 | AD15: =D15*640 -> 100480 | AE15: =AD15*0.6 -> 60288 | AF15: =G30*C15*AE15*0.001 -> 289.3824 | AG15: =D15*900 -> 141300 | AH15: =D15*720 -> 113040 | AI15: =AH15*0.6 -> 67824 | AJ15: =G30*C15*AI15*0.001 -> 325.5552 | AK15: =D15*1000 -> 157000 | AL15: =D15*900 -> 141300 | AM15: =AL15*0.6 -> 84780 | AN15: =G30*C15*AM15*0.001 -> 406.944 | AO15: =D15*1200 -> 188400 | AP15: =D15*1080 -> 169560 | AQ15: =AP15*0.6 -> 101736 | AR15: =G30*C15*AQ15*0.001 -> 488.3328
B16: M18 | C16: 18 | D16: 192 | E16: =D16*300 -> 57600 | F16: =D16*180 -> 34560 | G16: =0.6*180*D16 -> 20736 | H16: =G30*G16*C16*0.001 -> 111.9744 | I16: =D16*400 -> 76800 | J16: =D16*240 -> 46080 | K16: =J16*0.6 -> 27648 | L16: =G30*K16*C16*0.001 -> 149.2992 | M16: =D16*400 -> 76800 | N16: =D16*320 -> 61440 | O16: =N16*0.6 -> 36864 | P16: =G30*O16*C16*0.001 -> 199.0656 | Q16: =D16*500 -> 96000 | R16: =D16*300 -> 57600 | S16: =R16*0.6 -> 34560 | T16: =G30*S16*C16*0.001 -> 186.624 | U16: =D16*500 -> 96000 | V16: =D16*400 -> 76800 | W16: =V16*0.6 -> 46080 | X16: =G30*C16*W16*0.001 -> 248.832 | Y16: =D16*600 -> 115200 | Z16: =D16*480 -> 92160 | AA16: =Z16*0.6 -> 55296 | AB16: =G30*C16*AA16*0.001 -> 298.5984 | AC16: =D16*800 -> 153600 | AD16: =D16*640 -> 122880 | AE16: =AD16*0.6 -> 73728 | AF16: =G30*C16*AE16*0.001 -> 398.1312 | AG16: =D16*900 -> 172800 | AH16: =D16*720 -> 138240 | AI16: =AH16*0.6 -> 82944 | AJ16: =G30*C16*AI16*0.001 -> 447.8976 | AK16: =D16*1000 -> 192000 | AL16: =D16*900 -> 172800 | AM16: =AL16*0.6 -> 103680 | AN16: =G30*C16*AM16*0.001 -> 559.872 | AO16: =D16*1200 -> 230400 | AP16: =D16*1080 -> 207360 | AQ16: =AP16*0.6 -> 124416 | AR16: =G30*C16*AQ16*0.001 -> 671.8464
B17: M20 | C17: 20 | D17: 245 | E17: =D17*300 -> 73500 | F17: =D17*180 -> 44100 | G17: =0.6*180*D17 -> 26460 | H17: =G30*G17*C17*0.001 -> 158.76 | I17: =D17*400 -> 98000 | J17: =D17*240 -> 58800 | K17: =J17*0.6 -> 35280 | L17: =G30*K17*C17*0.001 -> 211.68 | M17: =D17*400 -> 98000 | N17: =D17*320 -> 78400 | O17: =N17*0.6 -> 47040 | P17: =G30*O17*C17*0.001 -> 282.24 | Q17: =D17*500 -> 122500 | R17: =D17*300 -> 73500 | S17: =R17*0.6 -> 44100 | T17: =G30*S17*C17*0.001 -> 264.6 | U17: =D17*500 -> 122500 | V17: =D17*400 -> 98000 | W17: =V17*0.6 -> 58800 | X17: =G30*C17*W17*0.001 -> 352.8 | Y17: =D17*600 -> 147000 | Z17: =D17*480 -> 117600 | AA17: =Z17*0.6 -> 70560 | AB17: =G30*C17*AA17*0.001 -> 423.36 | AC17: =D17*800 -> 196000 | AD17: =D17*640 -> 156800 | AE17: =AD17*0.6 -> 94080 | AF17: =G30*C17*AE17*0.001 -> 564.48 | AG17: =D17*900 -> 220500 | AH17: =D17*720 -> 176400 | AI17: =AH17*0.6 -> 105840 | AJ17: =G30*C17*AI17*0.001 -> 635.04 | AK17: =D17*1000 -> 245000 | AL17: =D17*900 -> 220500 | AM17: =AL17*0.6 -> 132300 | AN17: =G30*C17*AM17*0.001 -> 793.8 | AO17: =D17*1200 -> 294000 | AP17: =D17*1080 -> 264600 | AQ17: =AP17*0.6 -> 158760 | AR17: =G30*C17*AQ17*0.001 -> 952.56
B18: M22 | C18: 22 | D18: 303 | E18: =D18*300 -> 90900 | F18: =D18*180 -> 54540 | G18: =0.6*180*D18 -> 32724 | H18: =G30*G18*C18*0.001 -> 215.9784 | I18: =D18*400 -> 121200 | J18: =D18*240 -> 72720 | K18: =J18*0.6 -> 43632 | L18: =G30*K18*C18*0.001 -> 287.9712 | M18: =D18*400 -> 121200 | N18: =D18*320 -> 96960 | O18: =N18*0.6 -> 58176 | P18: =G30*O18*C18*0.001 -> 383.9616 | Q18: =D18*500 -> 151500 | R18: =D18*300 -> 90900 | S18: =R18*0.6 -> 54540 | T18: =G30*S18*C18*0.001 -> 359.964 | U18: =D18*500 -> 151500 | V18: =D18*400 -> 121200 | W18: =V18*0.6 -> 72720 | X18: =G30*C18*W18*0.001 -> 479.952 | Y18: =D18*600 -> 181800 | Z18: =D18*480 -> 145440 | AA18: =Z18*0.6 -> 87264 | AB18: =G30*C18*AA18*0.001 -> 575.9424 | AC18: =D18*800 -> 242400 | AD18: =D18*640 -> 193920 | AE18: =AD18*0.6 -> 116352 | AF18: =G30*C18*AE18*0.001 -> 767.9232 | AG18: =D18*900 -> 272700 | AH18: =D18*720 -> 218160 | AI18: =AH18*0.6 -> 130896 | AJ18: =G30*C18*AI18*0.001 -> 863.9136 | AK18: =D18*1000 -> 303000 | AL18: =D18*900 -> 272700 | AM18: =AL18*0.6 -> 163620 | AN18: =G30*C18*AM18*0.001 -> 1079.892 | AO18: =D18*1200 -> 363600 | AP18: =D18*1080 -> 327240 | AQ18: =AP18*0.6 -> 196344 | AR18: =G30*C18*AQ18*0.001 -> 1295.8704
B19: M24 | C19: 24 | D19: 353 | E19: =D19*300 -> 105900 | F19: =D19*180 -> 63540 | G19: =0.6*180*D19 -> 38124 | H19: =G30*G19*C19*0.001 -> 274.4928 | I19: =D19*400 -> 141200 | J19: =D19*240 -> 84720 | K19: =J19*0.6 -> 50832 | L19: =G30*K19*C19*0.001 -> 365.9904 | M19: =D19*400 -> 141200 | N19: =D19*320 -> 112960 | O19: =N19*0.6 -> 67776 | P19: =G30*O19*C19*0.001 -> 487.9872 | Q19: =D19*500 -> 176500 | R19: =D19*300 -> 105900 | S19: =R19*0.6 -> 63540 | T19: =G30*S19*C19*0.001 -> 457.488 | U19: =D19*500 -> 176500 | V19: =D19*400 -> 141200 | W19: =V19*0.6 -> 84720 | X19: =G30*C19*W19*0.001 -> 609.984 | Y19: =D19*600 -> 211800 | Z19: =D19*480 -> 169440 | AA19: =Z19*0.6 -> 101664 | AB19: =G30*C19*AA19*0.001 -> 731.9808 | AC19: =D19*800 -> 282400 | AD19: =D19*640 -> 225920 | AE19: =AD19*0.6 -> 135552 | AF19: =G30*C19*AE19*0.001 -> 975.9744 | AG19: =D19*900 -> 317700 | AH19: =D19*720 -> 254160 | AI19: =AH19*0.6 -> 152496 | AJ19: =G30*C19*AI19*0.001 -> 1097.9712 | AK19: =D19*1000 -> 353000 | AL19: =D19*900 -> 317700 | AM19: =AL19*0.6 -> 190620 | AN19: =G30*C19*AM19*0.001 -> 1372.464 | AO19: =D19*1200 -> 423600 | AP19: =D19*1080 -> 381240 | AQ19: =AP19*0.6 -> 228744 | AR19: =G30*C19*AQ19*0.001 -> 1646.9568
B20: M27 | C20: 27 | D20: 459 | E20: =D20*300 -> 137700 | F20: =D20*180 -> 82620 | G20: =0.6*180*D20 -> 49572 | H20: =G30*G20*C20*0.001 -> 401.5332 | I20: =D20*400 -> 183600 | J20: =D20*240 -> 110160 | K20: =J20*0.6 -> 66096 | L20: =G30*K20*C20*0.001 -> 535.3776 | M20: =D20*400 -> 183600 | N20: =D20*320 -> 146880 | O20: =N20*0.6 -> 88128 | P20: =G30*O20*C20*0.001 -> 713.8368 | Q20: =D20*500 -> 229500 | R20: =D20*300 -> 137700 | S20: =R20*0.6 -> 82620 | T20: =G30*S20*C20*0.001 -> 669.222 | U20: =D20*500 -> 229500 | V20: =D20*400 -> 183600 | W20: =V20*0.6 -> 110160 | X20: =G30*C20*W20*0.001 -> 892.296 | Y20: =D20*600 -> 275400 | Z20: =D20*480 -> 220320 | AA20: =Z20*0.6 -> 132192 | AB20: =G30*C20*AA20*0.001 -> 1070.7552 | AC20: =D20*800 -> 367200 | AD20: =D20*640 -> 293760 | AE20: =AD20*0.6 -> 176256 | AF20: =G30*C20*AE20*0.001 -> 1427.6736 | AG20: =D20*900 -> 413100 | AH20: =D20*720 -> 330480 | AI20: =AH20*0.6 -> 198288 | AJ20: =G30*C20*AI20*0.001 -> 1606.1328 | AK20: =D20*1000 -> 459000 | AL20: =D20*900 -> 413100 | AM20: =AL20*0.6 -> 247860 | AN20: =G30*C20*AM20*0.001 -> 2007.666 | AO20: =D20*1200 -> 550800 | AP20: =D20*1080 -> 495720 | AQ20: =AP20*0.6 -> 297432 | AR20: =G30*C20*AQ20*0.001 -> 2409.1992
B21: M30 | C21: 30 | D21: 561 | E21: =D21*300 -> 168300 | F21: =D21*180 -> 100980 | G21: =0.6*180*D21 -> 60588 | H21: =G30*G21*C21*0.001 -> 545.292 | I21: =D21*400 -> 224400 | J21: =D21*240 -> 134640 | K21: =J21*0.6 -> 80784 | L21: =G30*K21*C21*0.001 -> 727.056 | M21: =D21*400 -> 224400 | N21: =D21*320 -> 179520 | O21: =N21*0.6 -> 107712 | P21: =G30*O21*C21*0.001 -> 969.408 | Q21: =D21*500 -> 280500 | R21: =D21*300 -> 168300 | S21: =R21*0.6 -> 100980 | T21: =G30*S21*C21*0.001 -> 908.82 | U21: =D21*500 -> 280500 | V21: =D21*400 -> 224400 | W21: =V21*0.6 -> 134640 | X21: =G30*C21*W21*0.001 -> 1211.76 | Y21: =D21*600 -> 336600 | Z21: =D21*480 -> 269280 | AA21: =Z21*0.6 -> 161568 | AB21: =G30*C21*AA21*0.001 -> 1454.112 | AC21: =D21*800 -> 448800 | AD21: =D21*640 -> 359040 | AE21: =AD21*0.6 -> 215424 | AF21: =G30*C21*AE21*0.001 -> 1938.816 | AG21: =D21*900 -> 504900 | AH21: =D21*720 -> 403920 | AI21: =AH21*0.6 -> 242352 | AJ21: =G30*C21*AI21*0.001 -> 2181.168 | AK21: =D21*1000 -> 561000 | AL21: =D21*900 -> 504900 | AM21: =AL21*0.6 -> 302940 | AN21: =G30*C21*AM21*0.001 -> 2726.46 | AO21: =D21*1200 -> 673200 | AP21: =D21*1080 -> 605880 | AQ21: =AP21*0.6 -> 363528 | AR21: =G30*C21*AQ21*0.001 -> 3271.752
B22: M33 | C22: 33 | D22: 694 | E22: =D22*300 -> 208200 | F22: =D22*180 -> 124920 | G22: =0.6*180*D22 -> 74952 | H22: =G30*G22*C22*0.001 -> 742.0248 | I22: =D22*400 -> 277600 | J22: =D22*240 -> 166560 | K22: =J22*0.6 -> 99936 | L22: =G30*K22*C22*0.001 -> 989.3664 | M22: =D22*400 -> 277600 | N22: =D22*320 -> 222080 | O22: =N22*0.6 -> 133248 | P22: =G30*O22*C22*0.001 -> 1319.1552 | Q22: =D22*500 -> 347000 | R22: =D22*300 -> 208200 | S22: =R22*0.6 -> 124920 | T22: =G30*S22*C22*0.001 -> 1236.708 | U22: =D22*500 -> 347000 | V22: =D22*400 -> 277600 | W22: =V22*0.6 -> 166560 | X22: =G30*C22*W22*0.001 -> 1648.944 | Y22: =D22*600 -> 416400 | Z22: =D22*480 -> 333120 | AA22: =Z22*0.6 -> 199872 | AB22: =G30*C22*AA22*0.001 -> 1978.7328 | AC22: =D22*800 -> 555200 | AD22: =D22*640 -> 444160 | AE22: =AD22*0.6 -> 266496 | AF22: =G30*C22*AE22*0.001 -> 2638.3104 | AG22: =D22*900 -> 624600 | AH22: =D22*720 -> 499680 | AI22: =AH22*0.6 -> 299808 | AJ22: =G30*C22*AI22*0.001 -> 2968.0992 | AK22: =D22*1000 -> 694000 | AL22: =D22*900 -> 624600 | AM22: =AL22*0.6 -> 374760 | AN22: =G30*C22*AM22*0.001 -> 3710.124 | AO22: =D22*1200 -> 832800 | AP22: =D22*1080 -> 749520 | AQ22: =AP22*0.6 -> 449712 | AR22: =G30*C22*AQ22*0.001 -> 4452.1488
B23: M36 | C23: 36 | D23: 817 | E23: =D23*300 -> 245100 | F23: =D23*180 -> 147060 | G23: =0.6*180*D23 -> 88236 | H23: =G30*G23*C23*0.001 -> 952.9488 | I23: =D23*400 -> 326800 | J23: =D23*240 -> 196080 | K23: =J23*0.6 -> 117648 | L23: =G30*K23*C23*0.001 -> 1270.5984 | M23: =D23*400 -> 326800 | N23: =D23*320 -> 261440 | O23: =N23*0.6 -> 156864 | P23: =G30*O23*C23*0.001 -> 1694.1312 | Q23: =D23*500 -> 408500 | R23: =D23*300 -> 245100 | S23: =R23*0.6 -> 147060 | T23: =G30*S23*C23*0.001 -> 1588.248 | U23: =D23*500 -> 408500 | V23: =D23*400 -> 326800 | W23: =V23*0.6 -> 196080 | X23: =G30*C23*W23*0.001 -> 2117.664 | Y23: =D23*600 -> 490200 | Z23: =D23*480 -> 392160 | AA23: =Z23*0.6 -> 235296 | AB23: =G30*C23*AA23*0.001 -> 2541.1968 | AC23: =D23*800 -> 653600 | AD23: =D23*640 -> 522880 | AE23: =AD23*0.6 -> 313728 | AF23: =G30*C23*AE23*0.001 -> 3388.2624 | AG23: =D23*900 -> 735300 | AH23: =D23*720 -> 588240 | AI23: =AH23*0.6 -> 352944 | AJ23: =G30*C23*AI23*0.001 -> 3811.7952 | AK23: =D23*1000 -> 817000 | AL23: =D23*900 -> 735300 | AM23: =AL23*0.6 -> 441180 | AN23: =G30*C23*AM23*0.001 -> 4764.744 | AO23: =D23*1200 -> 980400 | AP23: =D23*1080 -> 882360 | AQ23: =AP23*0.6 -> 529416 | AR23: =G30*C23*AQ23*0.001 -> 5717.6928
B24: M39 | C24: 39 | D24: 976 | E24: =D24*300 -> 292800 | F24: =D24*180 -> 175680 | G24: =0.6*180*D24 -> 105408 | H24: =G30*G24*C24*0.001 -> 1233.2736 | I24: =D24*400 -> 390400 | J24: =D24*240 -> 234240 | K24: =J24*0.6 -> 140544 | L24: =G30*K24*C24*0.001 -> 1644.3648 | M24: =D24*400 -> 390400 | N24: =D24*320 -> 312320 | O24: =N24*0.6 -> 187392 | P24: =G30*O24*C24*0.001 -> 2192.4864 | Q24: =D24*500 -> 488000 | R24: =D24*300 -> 292800 | S24: =R24*0.6 -> 175680 | T24: =G30*S24*C24*0.001 -> 2055.456 | U24: =D24*500 -> 488000 | V24: =D24*400 -> 390400 | W24: =V24*0.6 -> 234240 | X24: =G30*C24*W24*0.001 -> 2740.608 | Y24: =D24*600 -> 585600 | Z24: =D24*480 -> 468480 | AA24: =Z24*0.6 -> 281088 | AB24: =G30*C24*AA24*0.001 -> 3288.7296 | AC24: =D24*800 -> 780800 | AD24: =D24*640 -> 624640 | AE24: =AD24*0.6 -> 374784 | AF24: =G30*C24*AE24*0.001 -> 4384.9728 | AG24: =D24*900 -> 878400 | AH24: =D24*720 -> 702720 | AI24: =AH24*0.6 -> 421632 | AJ24: =G30*C24*AI24*0.001 -> 4933.0944 | AK24: =D24*1000 -> 976000 | AL24: =D24*900 -> 878400 | AM24: =AL24*0.6 -> 527040 | AN24: =G30*C24*AM24*0.001 -> 6166.368 | AO24: =D24*1200 -> 1171200 | AP24: =D24*1080 -> 1054080 | AQ24: =AP24*0.6 -> 632448 | AR24: =G30*C24*AQ24*0.001 -> 7399.6416
A29: 表 一 | B29: 预紧力矩K值表 | H29: 表 二 | I29: 紧螺栓连接的许用应力级安全系数 | P29: 表 三 | Q29: 许用剪切和挤压应力及安全系数
B30: 摩擦表面状况 | D30: 有润滑 | E30: 无润滑 | F30: K= | G30: 0.3 | I30: 许用应力 | J30: 不控制预紧力时的安全系数 | N30: 控制预紧力时的安全系数 | Q30: 许用应力及安全系数及被连接材料 | S30: 剪应力 | U30: 挤压
S31: 许用应力 | T31: S | U31: 许用应力 | V31: S
B32: 精加工表面 | D32: 0.1 | E32: 0.12 | I32: [σ]=σs/S | J32: 直径/材料 | K32: M6-M16 | L32: M16-M30 | M32: M30-M60 | N32: 不分直径 | Q32: 钢 | S32: [τ]=σs/S | T32: 2.5 | U32: [σp]=σs/S | V32: 1.25
B33: 一般加工表面 | D33: 0.13-0.15 | E33: 0.18-0.21
B34: 表面氧化 | D34: 0.2 | E34: 0.24 | J34: 碳钢/合金钢 | K34: 4-3/5-4 | L34: 3-2/4-3 | M34: 2-1.3/2.5 | N34: 1.2-1.5 | Q34: 铸铁 | U34: [σp]=σb/S | V34: 2-2.5
B35: 镀锌表面 | D35: 0.18 | E35: 0.22
B36: 干燥的粗加工表面 | D36: 0.26-0.3 | Q36: 静载荷 | U36: [σp]=σs/S | V36: 1-1.25
B37: 注：请选择相应的预紧力矩K值输入蓝色框内！ | U37: [σp]=σb/S | V37: 2-2.5
Q38: 变载荷 | T38: 3.5-5 | U38: [σp]=σs/S | V38: 1.6-2
U39: [σp]=σb/S | V39: 2.5-3.5

Sheet CNC加工参数
A1: 鹏程电脑锣
A2: CNC 加 工 参 数
A3: 刀具 | C3: 一般钢料 | I3: 加硬钢料 | O3: 铜料 | U3: 备 注
A4: 刀径 | B4: 类型 | C4: 开粗 | F4: 光刀 | I4: 开粗 | L4: 光刀 | O4: 开粗 | R4: 光刀
C5: 转速(S) | D5: 进给(F) | E5: step | F5: 转速(S) | G5: 进给(F) | H5: step | I5: 转速(S) | J5: 进给(F) | K5: step | L5: 转速(S) | M5: 进给(F) | N5: step | O5: 转速(S) | P5: 进给(F) | Q5: step | R5: 转速(S) | S5: 进给(F) | T5: step
A6: φ16 | B6: R8普长飞刀 | C6: 2200 | D6: 1500 | E6: 0.6 | F6: 2600 | G6: 1600 | H6: 0.14 | I6: 2000 | J6: 1500 | K6: 0.5 | L6: 3000 | M6: 2000 | N6: 0.14 | O6: 2500 | P6: 1500 | Q6: 0.8 | R6: 3200 | S6: 1650 | T6: 0.15 | U6: 加硬钢料最适用
B7: R8加长飞刀 | C7: 2200 | D7: 1300 | E7: 0.6 | F7: 2500 | G7: 1500 | H7: 0.14 | I7: 2000 | J7: 1200 | K7: 0.5 | L7: 2800 | M7: 1600 | N7: 0.14 | O7: 2500 | P7: 1500 | Q7: 0.6 | R7: 3000 | S7: 1500 | T7: 0.15 | U7: 较大工件常用
B8: R8粗飞刀 | C8: 1600 | D8: 1200 | E8: 0.5 | F8: 1750 | G8: 1400 | H8: 0.14 | O8: 2400 | P8: 1300 | Q8: 0.5 | U8: 一般不用作光刀
B9: R8白钢粗刀 | C9: 1600 | D9: 1200 | E9: 0.6 | F9: 1750 | G9: 1400 | H9: 0.14 | O9: 1800 | P9: 1250 | Q9: 0.8 | U9: 铜公开粗最适用
B10: R8钨钢光刀 | F10: 2500 | G10: 1500 | H10: 0.15 | L10: 2500 | M10: 1800 | N10: 0.15 | O10: 3000 | P10: 1200 | Q10: 0.5 | R10: 3000 | S10: 1650 | T10: 0.15 | U10: 一般不用作钢料光刀
B11: R4普长飞刀 | C11: 2000 | D11: 1400 | E11: 0.4 | F11: 2200 | G11: 1500 | H11: 0.18 | I11: 2000 | J11: 1200 | K11: 0.3 | L11: 2000 | M11: 1500 | N11: 0.18 | O11: 2500 | P11: 1400 | Q11: 0.5 | U11: 一般不作光刀
B12: R0.8加长飞刀 | C12: 1800 | D12: 1250 | E12: 0.25 | F12: 2000 | G12: 1500 | H12: 0.12 | I12: 1800 | J12: 1200 | K12: 0.15 | L12: 2000 | M12: 1400 | N12: 0.12 | O12: 2400 | P12: 1400 | Q12: 0.5 | R12: 2500 | S12: 1600 | T12: 0.12 | U12: 光刀宜不准数
B13: R0.8普长飞刀 | C13: 1800 | D13: 1500 | E13: 0.5 | F13: 2000 | G13: 1600 | H13: 0.12 | I13: 1800 | J13: 1350 | K13: 0.25 | L13: 1800 | M13: 1500 | N13: 0.12 | O13: 2500 | P13: 1500 | Q13: 1 | R13: 3000 | S13: 1650 | T13: 0.12 | U13: 常用飞刀
B14: R0.4加长飞刀 | C14: 1800 | D14: 1250 | E14: 0.25 | F14: 22000 | G14: 1400 | H14: 0.1 | I14: 1800 | J14: 1000 | K14: 0.2 | L14: 2100 | M14: 1400 | N14: 0.1 | O14: 2500 | P14: 1400 | Q14: 0.4 | R14: 2600 | S14: 1500 | T14: 0.1 | U14: 不宜铜公光刀
B15: R0.4普长飞刀 | C15: 1850 | D15: 1500 | E15: 0.4 | F15: 2000 | G15: 1500 | H15: 0.1 | I15: 1800 | J15: 1500 | K15: 0.25 | L15: 2000 | M15: 1500 | N15: 0.1 | O15: 2500 | P15: 1500 | Q15: 0.6 | R15: 2800 | S15: 1650 | T15: 0.1 | U15: 不宜铜公光刀
B16: 白钢平底普长刀 | C16: 700 | D16: 1200 | E16: 0.4 | F16: 850 | G16: 1200 | H16: 0.1 | O16: 1100 | P16: 1600 | Q16: 1.5 | R16: 1500 | S16: 1200 | T16: 0.1 | U16: 最常用白钢刀<常用侧锋>
B17: 白钢平底加长刀 | C17: 700 | D17: 1000 | E17: 0.3 | F17: 850 | G17: 1100 | H17: 0.1 | O17: 1100 | P17: 1500 | Q17: 1.2 | R17: 1500 | S17: 1100 | T17: 0.1 | U17: 常用侧锋光刀
B18: 钨钢平底加长刀 | C18: 1200 | D18: 1100 | E18: 0.4 | F18: 1350 | G18: 1500 | H18: 0.1 | I18: 1100 | J18: 1200 | K18: 0.4 | L18: 1300 | M18: 1500 | N18: 0.1 | O18: 1500 | P18: 1400 | Q18: 1 | R18: 1800 | S18: 1500 | T18: 0.1 | U18: 常用侧锋光刀
B19: 钨钢平底普长刀 | C19: 1200 | D19: 1400 | E19: 0.5 | F19: 1350 | G19: 1600 | H19: 0.1 | I19: 1100 | J19: 1300 | K19: 0.5 | L19: 1300 | M19: 1600 | N19: 0.1 | O19: 1500 | P19: 1600 | Q19: 1.2 | R19: 1800 | S19: 1600 | T19: 0.1 | U19: 常用侧锋光刀
A20: φ12 | B20: R6加长飞刀 | C20: 1800 | D20: 1350 | E20: 0.5 | F20: 2200 | G20: 1600 | H20: 0.14 | I20: 1650 | J20: 1200 | K20: 0.4 | L20: 2000 | M20: 1500 | N20: 0.14 | O20: 2000 | P20: 1400 | Q20: 0.5 | R20: 2500 | S20: 1600 | T20: 0.14 | U20: 一般不作铜公光刀
B21: R6白钢粗刀 | C21: 1600 | D21: 1300 | E21: 0.5 | F21: 1600 | G21: 1300 | H21: 0.14 | O21: 1800 | P21: 1400 | Q21: 0.8 | R21: 2100 | S21: 1500 | T21: 0.14
B22: R6钨钢加长刀 | C22: 2000 | D22: 1250 | E22: 0.4 | F22: 2200 | G22: 1500 | H22: 0.14 | I22: 2000 | J22: 1200 | K22: 0.5 | L22: 2200 | M22: 1600 | N22: 0.12 | O22: 2400 | P22: 1400 | Q22: 0.6 | R22: 3000 | S22: 1500 | T22: 0.14
B23: R6钨钢普长刀 | C23: 2000 | D23: 1500 | E23: 0.5 | F23: 2200 | G23: 1600 | H23: 0.14 | I23: 2000 | J23: 1350 | K23: 0.5 | L23: 2200 | M23: 1800 | N23: 0.14 | O23: 2400 | P23: 1500 | Q23: 0.6 | R23: 3000 | S23: 1600 | T23: 0.14
B24: 平底白钢加长刀 | C24: 1000 | D24: 900 | E24: 0.3 | F24: 1300 | G24: 1300 | H24: 0.1 | O24: 1300 | P24: 1500 | Q24: 1 | R24: 1400 | S24: 1200 | T24: 0.1
B25: 平底白钢普长刀 | C25: 1000 | D25: 1100 | E25: 0.5 | F25: 1300 | G25: 1400 | H25: 0.1 | O25: 1300 | P25: 1600 | Q25: 1.2 | R25: 1400 | S25: 1300 | T25: 0.1 | U25: 最常用粗刀
B26: 平底钨钢加长刀 | C26: 1200 | D26: 1100 | E26: 0.35 | F26: 2000 | G26: 1500 | H26: 0.1 | I26: 1100 | J26: 1000 | K26: 0.2 | L26: 1600 | M26: 1500 | N26: 0.1 | O26: 1600 | P26: 1400 | Q26: 1 | R26: 2000 | S26: 1400 | T26: 0.1
B27: 平底钨钢普长刀 | C27: 1200 | D27: 1300 | E27: 0.5 | F27: 2000 | G27: 1600 | H27: 0.1 | I27: 1100 | J27: 1200 | K27: 0.3 | L27: 1600 | M27: 1600 | N27: 0.1 | O27: 1600 | P27: 1600 | Q27: 1.2 | R27: 2000 | S27: 1500 | T27: 0.1 | U27: 最常用光刀
A28: φ10 | B28: R5普长飞刀 | C28: 2000 | D28: 1300 | E28: 0.4 | F28: 2500 | G28: 1500 | H28: 0.12 | I28: 2000 | J28: 1100 | K28: 0.3 | L28: 2400 | M28: 1500 | N28: 0.12 | O28: 2200 | P28: 1200 | Q28: 0.5 | R28: 2500 | S28: 1400 | T28: 0.12 | U28: 一般不用作光刀
B29: R5白钢粗刀 | C29: 1600 | D29: 1200 | E29: 0.5 | F29: 1650 | G29: 1350 | H29: 0.12 | O29: 1800 | P29: 1200 | Q29: 0.6 | R29: 2100 | S29: 1500 | T29: 0.12
B30: R5钨钢普长刀 | C30: 2000 | D30: 1200 | E30: 0.5 | F30: 2400 | G30: 1400 | H30: 0.12 | I30: 2000 | J30: 1500 | K30: 0.5 | L30: 2300 | M30: 1500 | N30: 0.12 | O30: 3000 | P30: 1600 | Q30: 0.5 | R30: 3200 | S30: 1800 | T30: 0.12 | U30: 最常用光刀
B31: R5钨钢加长刀 | C31: 2000 | D31: 1100 | E31: 0.4 | F31: 2400 | G31: 1300 | H31: 0.12 | I31: 2000 | J31: 1400 | K31: 0.5 | L31: 2300 | M31: 1400 | N31: 0.12 | O31: 3000 | P31: 1400 | Q31: 0.4 | R31: 3200 | S31: 1500 | T31: 0.12
B32: 白钢普长平底刀 | C32: 1100 | D32: 1200 | E32: 0.4 | F32: 1400 | G32: 1250 | H32: 0.1 | O32: 1500 | P32: 1350 | Q32: 1 | R32: 1650 | S32: 1350 | T32: 0.1 | U32: 常用刀具
B33: 钨钢普长平底刀 | C33: 1500 | D33: 1200 | E33: 0.4 | F33: 1800 | G33: 1500 | H33: 0.1 | I33: 1350 | J33: 1250 | K33: 0.3 | L33: 1400 | M33: 1400 | N33: 0.1 | O33: 2000 | P33: 1500 | Q33: 1 | R33: 2100 | S33: 1600 | T33: 0.1 | U33: 常用刀具
B34: 钨钢加长平底刀 | C34: 1500 | D34: 1000 | E34: 0.3 | F34: 1700 | G34: 1300 | H34: 0.1 | I34: 1350 | J34: 1100 | K34: 0.2 | L34: 1400 | M34: 1300 | N34: 0.1 | O34: 2000 | P34: 1350 | Q34: 0.8 | R34: 2100 | S34: 1500 | T34: 0.1
A35: φ50 φ63 | B35: R6加长飞刀 | C35: 1300 | D35: 1500 | E35: 0.3 | F35: 1400 | G35: 1400 | H35: 0.15 | L35: 1200 | M35: 1200 | N35: 0.15 | U35: 光刀误差较大
B36: R6普长飞刀 | C36: 1100 | D36: 1800 | E36: 0.8 | F36: 1250 | G36: 1800 | H36: 0.25 | I36: 900 | J36: 1500 | K36: 0.4 | L36: 1000 | M36: 1500 | N36: 0.2 | O36: 1600 | P36: 1800 | Q36: 1 | R36: 1800 | S36: 1800 | T36: 0.25 | U36: 用作开粗及光平面
A37: 鹏程电脑锣
A38: CNC 加 工 参 数
A39: 刀具 | C39: 一般钢料 | I39: 加硬钢料 | O39: 铜料 | U39: 备 注
A40: 刀径 | B40: 类型 | C40: 开粗 | F40: 光刀 | I40: 开粗 | L40: 光刀 | O40: 开粗 | R40: 光刀
...

Sheet 钢料加工参数参考表
A1: 钢料加工参数参考表（公众号：曼仑）
A2: 八千转以下加工中心切削参数 | J2: 最低转速为5000的雕铣机
A3: 刀具名称 | B3: 转速 | C3: 进给 | D3: 每刀切削深度 | E3: 步距 | J3: 刀具名称 | K3: 转速 | L3: 进给 | M3: 每刀切削深度 | N3: 步距
A4: D50R5 | B4: 1500 | C4: 3000 | D4: 0.8-0.6 | E4: 75%(刀具直径） | J4: D16 | K4: 6000 | L4: 9000 | M4: 0.05 | N4: 75%刀具直径
A5: D35R5 | B5: 1800 | C5: 2500 | D5: 0.5-0.8 | E5: 75%(刀具直径） | J5: D12 | K5: 9000 | L5: 9000 | M5: 0.05 | N5: 75%刀具直径
A6: D30R5 | B6: 1800 | C6: 2200 | D6: 0.5-0.6 | E6: 75%(刀具直径） | J6: D10 | K6: 12000 | L6: 9000 | M6: 0.03-0.05 | N6: 75%刀具直径
A7: D25R5 | B7: 2000 | C7: 2200 | D7: 0.5-0.6 | E7: 75%(刀具直径） | J7: D8 | K7: 12000 | L7: 7000 | M7: 0.05 | N7: 75%刀具直径
A8: D20R5 | B8: 2000 | C8: 2200 | D8: 0.5-0.6 | E8: 75%(刀具直径） | J8: D6 | K8: 13000 | L8: 6000 | M8: 0.03-0.05 | N8: 75%刀具直径
A9: D20R4 | B9: 2200 | C9: 2200 | D9: 0.5-0.6 | E9: 75%(刀具直径） | J9: D5 | K9: 13000 | L9: 5000 | M9: 0.03 | N9: 75%刀具直径
A10: D20R0.8 | B10: 2000 | C10: 1500 | D10: 0.35 | E10: 75%(刀具直径） | J10: D4 | K10: 13000 | L10: 4000 | M10: 0.02 | N10: 75%刀具直径
A11: D16R4 | B11: 2500 | C11: 2000 | D11: 0.35 | E11: 75%(刀具直径） | J11: D3 | K11: 14000 | L11: 3500 | M11: 0.02 | N11: 75%刀具直径
A12: D16R0.8 | B12: 2800 | C12: 2000 | D12: 0.35 | E12: 75%(刀具直径） | J12: D2 | K12: 15000 | L12: 3000 | M12: 0.01 | N12: 50%刀具直径
A13: D12R0.4 | B13: 2800 | C13: 1600 | D13: 0.25 | E13: 75%(刀具直径） | J13: D1.5 | K13: 15000 | L13: 1200 | M13: 0.01 | N13: 50%刀具直径
A14: 以上刀具都是装刀片的刀粒刀（R4，R5刀片比较适合开粗。 R0.4和R0.8刀片比较适合中铣，也可以用来光平面） | J14: D1 | K14: 15000 | L14: 1000 | M14: 0.01 | N14: 50%刀具直径
J15: D0.8 | K15: 15000 | L15: 800 | M15: 0.01 | N15: 50%刀具直径
A16: 刀具名称 | B16: 转速 | C16: 进给 | D16: 每刀切削深度 | E16: 步距 | N16: 50%刀具直径
A17: D20 | B17: 2200 | C17: 2000 | D17: 0.3 | E17: 75%(刀具直径） | J17: D0.6 | K17: 15000 | L17: 600 | M17: 0.01 | N17: 50%刀具直径
A18: D16 | B18: 3000 | C18: 2000 | D18: 0.3 | E18: 75%(刀具直径） | J18: D0.5 | K18: 15000 | L18: 400 | M18: 0.01 | N18: 50%刀具直径
A19: D12 | B19: 3500 | C19: 2000 | D19: 0.25-0.28 | E19: 75%(刀具直径）
A20: D10 | B20: 3600 | C20: 1800 | D20: 0.22-0.25 | E20: 75%(刀具直径）
A21: D8 | B21: 3800-4000 | C21: 1800 | D21: 0.2-0.22 | E21: 75%(刀具直径） | J21: 刀具名称 | K21: 转速 | L21: 进给 | M21: 每刀切削深度 | N21: 步距
A22: D6 | B22: 4200-4500 | C22: 1600 | D22: 0.15-0.18 | E22: 75%(刀具直径） | J22: D12R0.5 | K22: 12000 | L22: 9000 | M22: 0.05 | N22: 75%(刀具直径去圆角后的75%）
A23: D5 | B23: 4300-4600 | C23: 1600 | D23: 0.12-0.15 | E23: 75%(刀具直径） | J23: D10R0.5 | K23: 12000 | L23: 7000 | M23: 0.05 | N23: 75%(刀具直径去圆角后的75%）
A24: D4 | B24: 4500-4800 | C24: 1300-1500 | D24: 0.11-0.12 | E24: 75%(刀具直径） | J24: D8R0.5 | K24: 13000 | L24: 6000 | M24: 0.03 | N24: 75%(刀具直径去圆角后的75%）
A25: D3 | B25: 4600-5000 | C25: 800-1000 | D25: 0.06 | E25: 50%(刀具直径） | J25: D6R0.5 | K25: 13000 | L25: 5000 | M25: 0.03 | N25: 75%(刀具直径去圆角后的75%）
A26: D2 | B26: 5000-5200 | C26: 400-600 | D26: 0.02-0.03 | E26: 50%(刀具直径） | J26: D4R0.5 | K26: 13000 | L26: 4000 | M26: 0.02 | N26: 75%(刀具直径去圆角后的75%）
A27: D1.5 | B27: 5500 | C27: 200-300 | D27: 0.01-0.02 | E27: 50%(刀具直径） | J27: D4R0.4 | K27: 14000 | L27: 3500 | M27: 0.02 | N27: 75%(刀具直径去圆角后的75%）
A28: D1 | B28: 5500-5800 | C28: 150-200 | D28: 0.01 | E28: 50%(刀具直径） | F28: 在加工钢料时，小口径铣刀比较少用到，如果有必要，可以拆电极。 | G28: 这些铣刀在实际加工中很少用于加工钢料 | J28: D3R0.5 | K28: 15000 | L28: 3000 | M28: 0.02 | N28: 75%(刀具直径去圆角后的75%）
A29: D0.8 | B29: 6000 | C29: 120 | D29: 0.01 | E29: 50%(刀具直径）
A30: D0.6 | B30: 6300 | C30: 100 | D30: 0.01 | E30: 50%(刀具直径）
A31: D0.5 | B31: 6500 | C31: 80 | D31: 0.01 | E31: 50%(刀具直径） | J31: 刀具名称 | K31: 转速 | L31: 进给 | M31: 每刀切削深度 | N31: 步距
A32: 以上都是平刀，在实际加工中开粗时步距一般为50%-70%，平面光面时步距一般为30%刀具直径 | J32: R6 | K32: 7000 | L32: 3500 | N32: 0.15-0.18
J33: R5 | K33: 8000 | L33: 3000 | N33: 0.13-0.16
J34: R4 | K34: 9000 | L34: 2800 | N34: 0.13-0.15
A35: 刀具名称 | B35: 转速 | C35: 进给 | D35: 每刀切削深度 | E35: 步距 | J35: R3 | K35: 10000 | L35: 2500 | N35: 0.12-0.15
A36: D12R0.5 | B36: 3800 | C36: 2500 | D36: 0.25-0.28 | E36: 75%(刀具直径去圆角后的75%） | J36: R2 | K36: 12000 | L36: 2000 | N36: 0.1-0.12
A37: D10R0.5 | B37: 3800 | C37: 2400 | D37: 0.22-0.25 | E37: 75%(刀具直径去圆角后的75%） | J37: R1.5 | K37: 13000 | L37: 1500 | N37: 0.06-0.08
A38: D8R0.5 | B38: 4000-4200 | C38: 2200 | D38: 0.2 | E38: 75%(刀具直径去圆角后的75%） | J38: R1 | K38: 15000 | L38: 1000 | N38: 0.02-0.03
A39: D6R0.5 | B39: 4200-4500 | C39: 1800 | D39: 0.15-0.18 | E39: 75%(刀具直径去圆角后的75%） | J39: R0.75 | K39: 15000 | L39: 800 | N39: 0.02
A40: D4R0.5 | B40: 4500-4800 | C40: 1300-1500 | D40: 0.1-0.13 | E40: 75%(刀具直径去圆角后的75%） | J40: R0.5 | K40: 15000 | L40: 600 | N40: 0.01
...

Sheet CNC钢料切削参数表
A1: CNC 钢料 切削参数表（高速机）（公众号：曼仑）
M2: 代码诠释：
M3: D=刀具直径 R=刀角半径
M4: F=进给速率 S=主轴转数
M5: Vc=线性切削速度 (m/min) Fz=每齿切削量(mm/tooth)
M6: Ae=径向进给量 (mm) Ap=轴向进给量(mm)
M7: 加工参数的注意事项：
M8: 1 当刀具长度在直径的5倍以内下列参数适用.切记!刀具长度不可大过直径的9倍
M9: 2 当刀具长度在直径的5倍以上时需将F/S值下调10%；Ae/Ap减小30%
M10: 3 工件在精加工之前需保证余量均匀；不可让刀具产生过大的切削负荷
H11: n=主轴转数（公式套用） | M11: 4 工件锐角处需做过渡圆角；钢料为R2、铜料为R1 石墨为R0.6
A12: 刀具 | B12: 开粗 | F12: 半精加工 | J12: 仿形精加工 | N12: 底面/侧面精加工 | R12: PL面仿形精加工
B13: Vc=150-300 Fz=0.15 | F13: Vc=160-280 Fz=0.13 | J13: Vc=50-350 Fz=0.09 | N13: Vc=260 Fz=0.03 | R13: Vc=200-260 Fz=0.13
B14: F | C14: S | D14: ae | E14: ap | F14: F | G14: S | H14: ae | I14: ap | J14: F | K14: S | L14: ae | M14: ap | N14: F | O14: S | P14: ae | Q14: ap | R14: F | S14: S | T14: ae | U14: ap
A15: D12 | B15: 3300 | C15: 4350 | D15: 7.5 | E15: 0.2 | F15: 3600 | G15: 6000 | H15: 7 | I15: 0.25 | J15: 3300 | K15: 9200 | L15: 0.1 | M15: 0.1 | N15: 800 | O15: 7000 | P15: 0.08 | Q15: 0.05
A16: D8 | B16: 3300 | C16: 6500 | D16: 5 | E16: 0.18 | F16: 3600 | G16: 8000 | H16: 5 | I16: 0.25 | J16: 3500 | K16: 9500 | L16: 0.1 | M16: 0.1 | N16: 800 | O16: 8500 | P16: 0.08 | Q16: 0.05
A17: D6 | B17: 3300 | C17: 8500 | D17: 3.5 | E17: 0.13 | F17: 3500 | G17: 9000 | H17: 3.5 | I17: 0.2 | J17: 3200 | K17: 11000 | L17: 0.07 | M17: 0.07 | N17: 800 | O17: 8500 | P17: 0.06 | Q17: 0.05
A18: D4 | B18: 3200 | C18: 12000 | D18: 2 | E18: 0.08 | F18: 3000 | G18: 12000 | H18: 2 | I18: 0.15 | J18: 3000 | K18: 12000 | L18: 0.05 | M18: 0.05 | N18: 700 | O18: 9000 | P18: 0.05 | Q18: 0.05
A19: D3 | F19: 3000 | G19: 12500 | H19: 1.5 | I19: 0.06 | J19: 2600 | K19: 12000 | L19: 0.035 | M19: 0.035 | N19: 700 | O19: 9500 | P19: 0.03 | Q19: 0.05
A20: D2
A21: D1.5
A22: D1
A23: D12R0.5 | B23: 3800 | C23: 5000 | D23: 7 | E23: 0.22 | F23: 3800 | G23: 6300 | H23: 7 | I23: 0.3 | J23: 3000 | K23: 8500 | L23: 0.22 | M23: 0.22 | N23: 850 | O23: 8000 | P23: 7 | Q23: 0.06 | R23: 3200 | S23: 8500 | T23: 0.25 | U23: 0.3
A24: D8R0.5 | B24: 3800 | C24: 7200 | D24: 4 | E24: 0.2 | F24: 3800 | G24: 8000 | H24: 4 | I24: 0.25 | J24: 3500 | K24: 9500 | L24: 0.2 | M24: 0.2 | N24: 850 | O24: 8500 | P24: 5 | Q24: 0.06 | R24: 3200 | S24: 9500 | T24: 0.25 | U24: 0.3
A25: D6R0.5 | B25: 3500 | C25: 8500 | D25: 3 | E25: 0.13 | F25: 3200 | G25: 9500 | H25: 3 | I25: 0.25 | J25: 3300 | K25: 11000 | L25: 0.2 | M25: 0.2 | N25: 850 | O25: 8500 | P25: 3 | Q25: 0.06 | R25: 3000 | S25: 10000 | T25: 0.2 | U25: 0.22
A26: D4R0.5 | B26: 3200 | C26: 12000 | D26: 2 | E26: 0.08 | F26: 3000 | G26: 12000 | H26: 2 | I26: 0.2 | J26: 3000 | K26: 12000 | L26: 0.15 | M26: 0.15 | N26: 700 | O26: 9000 | P26: 2 | Q26: 0.06 | R26: 3000 | S26: 13000 | T26: 0.17 | U26: 0.17
A27: R6 | B27: 2500 | C27: 5500 | D27: 0.35 | E27: 0.3 | F27: 3000 | G27: 7200 | H27: 0.35 | I27: 0.3 | J27: 2850 | K27: 8500 | L27: 0.22 | M27: 0.22 | R27: 3000 | S27: 8500 | T27: 0.35 | U27: 0.35
A28: R4 | B28: 3000 | C28: 7500 | D28: 0.35 | E28: 0.25 | F28: 3000 | G28: 8500 | H28: 0.35 | I28: 0.3 | J28: 2850 | K28: 9000 | L28: 0.22 | M28: 0.22 | R28: 3000 | S28: 10000 | T28: 0.32 | U28: 0.32
A29: R3 | B29: 3000 | C29: 9500 | D29: 0.3 | E29: 0.2 | F29: 2800 | G29: 10000 | H29: 0.3 | I29: 0.25 | J29: 3000 | K29: 11000 | L29: 0.18 | M29: 0.18 | R29: 3000 | S29: 12000 | T29: 0.27 | U29: 0.27
A30: R2 | B30: 3000 | C30: 12000 | D30: 0.25 | E30: 0.18 | F30: 2800 | G30: 12000 | H30: 0.22 | I30: 0.18 | J30: 3000 | K30: 12000 | L30: 0.18 | M30: 0.18 | R30: 2600 | S30: 13000 | T30: 0.23 | U30: 0.23
A31: R1.5 | F31: 2200 | G31: 13000 | H31: 0.15 | I31: 0.12 | J31: 2800 | K31: 13500 | L31: 0.15 | M31: 0.15 | R31: 2500 | S31: 13500 | T31: 0.17 | U31: 0.17
A33: 26ER0.8 | J33: 3000 | K33: 1650 | L33: 0.2 | M33: 0.22 | N33: 850 | O33: 1800 | P33: 16 | Q33: 0.1 | R33: 3000 | S33: 1800 | T33: 0.3 | U33: 0.3
A34: 21ER2
A35: 21ER0.8 | J35: 3000 | K35: 1800 | L35: 0.2 | M35: 0.18 | N35: 850 | O35: 1800 | P35: 10 | Q35: 0.1 | R35: 3000 | S35: 1800 | T35: 0.3 | U35: 0.3
A36: 17ER0.8
A37: 16BR8 | J37: 3200 | K37: 5000 | L37: 0.25 | M37: 0.25 | R37: 3500 | S37: 5000 | T37: 0.38 | U37: 0.38
A38: 12BR6 | J38: 3200 | K38: 5500 | L38: 0.22 | M38: 0.22 | R38: 3500 | S38: 5500 | T38: 0.35 | U38: 0.35
A39: 制表：刘亚超 2009-06-15 | M39: 审核：
A42: CNC 钢料 切削参数表（低速机）
M43: 代码诠释：
...

Sheet 尺寸链计算
A1: 设计尺寸链 | H1: 极值法 工艺尺寸链 | M1: 概率法 工艺尺寸链 | V1: 转换为非双向偏差
A2: 组成环尺寸 | H2: 组成环尺寸 | M2: 试算 组成环尺寸 | S2: 调整后组成环尺寸 | V2: 组成环尺寸
A3: 基本尺寸 | B3: 极限 偏差 | C3: 极限尺寸 | D3: 组成环属性 | F3: 选择加工 封闭环 | H3: 基本尺寸 | I3: 设定 偏差 | J3: 极限尺寸 | K3: 组成环属性 | M3: 基本尺寸 | N3: 原尺寸 双向偏差 | P3: 设定 偏差 | Q3: 公差 | R3: 极限尺寸 | S3: 基本尺寸 | T3: 极限尺寸 | U3: 组成环 属性 | V3: 基本尺寸 | W3: 极限偏差
A4: 42.2 | B4: 0 | C4: =IF(A4="","",A4+B4) -> 42.2 | D4: 增环 | F4: 封闭环 | H4: =IF(AND(F4<>"封闭环",A4<>""),A4,"") | J4: =IF(H4="","",H4+I4) | M4: =IF(AND(F4<>"封闭环",A4<>""),(C4+C5)/2,"") | N4: =IF(M4<>"","±","") | O4: =IF(M4<>"",ABS((B4+B5)/2),"") | Q4: =IF(M4<>"",P4*2,"") | R4: =IF(M4="","",M4+P4) | T4: =IF(S4="","",S4+P4) | U4: =IF(M4<>"",K4,"") | V4: =IF(AND(F4<>"封闭环",H4<>""),H4,"") | W4: =IF(V4<>"",T4-V4,"")
B5: -0.16 | C5: =IF(A4="","",A4+B5) -> 42.04 | J5: =IF(H4="","",H4+I5) | R5: =IF(M4="","",M4-P4) | T5: =IF(S4="","",S4-P4) | W5: =IF(V4<>"",T5-V4,"")
A6: 12.6 | B6: 0.11 | C6: =IF(A6="","",A6+B6) -> 12.71 | D6: 减环 | H6: =IF(AND(F6<>"封闭环",A6<>""),A6,"") -> 12.6 | I6: 0.11 | J6: =IF(H6="","",H6+I6) -> 12.71 | K6: 增环 | M6: =IF(AND(F6<>"封闭环",A6<>""),(C6+C7)/2,"") -> 12.655 | N6: =IF(M6<>"","±","") -> ± | O6: =IF(M6<>"",ABS((B6+B7)/2),"") -> 0.055 | P6: 0.05 | Q6: =IF(M6<>"",P6*2,"") -> 0.1 | R6: =IF(M6="","",M6+P6) -> 12.705 | S6: 12.65 | T6: =IF(S6="","",S6+P6) -> 12.7 | U6: =IF(M6<>"",K6,"") -> 增环 | V6: =IF(AND(F6<>"封闭环",H6<>""),H6,"") -> 12.6 | W6: =IF(V6<>"",T6-V6,"") -> 0.1
B7: 0 | C7: =IF(A6="","",A6+B7) -> 12.6 | I7: 0 | J7: =IF(H6="","",H6+I7) -> 12.6 | R7: =IF(M6="","",M6-P6) -> 12.605 | T7: =IF(S6="","",S6-P6) -> 12.6 | W7: =IF(V6<>"",T7-V6,"") -> 0
A8: 6 | B8: 0 | C8: =IF(A8="","",A8+B8) -> 6 | D8: 减环 | H8: =IF(AND(F8<>"封闭环",A8<>""),A8,"") -> 6 | I8: 0 | J8: =IF(H8="","",H8+I8) -> 6 | K8: 增环 | M8: =IF(AND(F8<>"封闭环",A8<>""),(C8+C9)/2,"") -> 5.9625 | N8: =IF(M8<>"","±","") -> ± | O8: =IF(M8<>"",ABS((B8+B9)/2),"") -> 0.0375 | P8: 0.038 | Q8: =IF(M8<>"",P8*2,"") -> 0.076 | R8: =IF(M8="","",M8+P8) -> 6.0005 | S8: 5.962 | T8: =IF(S8="","",S8+P8) -> 6 | U8: =IF(M8<>"",K8,"") -> 增环 | V8: =IF(AND(F8<>"封闭环",H8<>""),H8,"") -> 6 | W8: =IF(V8<>"",T8-V8,"") -> 0
B9: -0.075 | C9: =IF(A8="","",A8+B9) -> 5.925 | I9: -0.075 | J9: =IF(H8="","",H8+I9) -> 5.925 | R9: =IF(M8="","",M8-P8) -> 5.9245 | T9: =IF(S8="","",S8-P8) -> 5.924 | W9: =IF(V8<>"",T9-V8,"") -> -0.076
C10: =IF(A10="","",A10+B10) | H10: =IF(AND(F10<>"封闭环",A10<>""),A10,"") | J10: =IF(H10="","",H10+I10) | M10: =IF(AND(F10<>"封闭环",A10<>""),(C10+C11)/2,"") | N10: =IF(M10<>"","±","") | O10: =IF(M10<>"",ABS((B10+B11)/2),"") | Q10: =IF(M10<>"",P10*2,"") | R10: =IF(M10="","",M10+P10) | T10: =IF(S10="","",S10+P10) | U10: =IF(M10<>"",K10,"") | V10: =IF(AND(F10<>"封闭环",H10<>""),H10,"") | W10: =IF(V10<>"",T10-V10,"")
C11: =IF(A10="","",A10+B11) | J11: =IF(H10="","",H10+I11) | R11: =IF(M10="","",M10-P10) | T11: =IF(S10="","",S10-P10) | W11: =IF(V10<>"",T11-V10,"")
C12: =IF(A12="","",A12+B12) | H12: =IF(AND(F12<>"封闭环",A12<>""),A12,"") | J12: =IF(H12="","",H12+I12) | M12: =IF(AND(F12<>"封闭环",A12<>""),(C12+C13)/2,"") | N12: =IF(M12<>"","±","") | O12: =IF(M12<>"",ABS((B12+B13)/2),"") | Q12: =IF(M12<>"",P12*2,"") | R12: =IF(M12="","",M12+P12) | T12: =IF(S12="","",S12+P12) | U12: =IF(M12<>"",K12,"") | V12: =IF(AND(F12<>"封闭环",H12<>""),H12,"") | W12: =IF(V12<>"",T12-V12,"")
C13: =IF(A12="","",A12+B13) | J13: =IF(H12="","",H12+I13) | R13: =IF(M12="","",M12-P12) | T13: =IF(S12="","",S12-P12) | W13: =IF(V12<>"",T13-V12,"")
C14: =IF(A14="","",A14+B14) | H14: =IF(AND(F14<>"封闭环",A14<>""),A14,"") | J14: =IF(H14="","",H14+I14) | M14: =IF(AND(F14<>"封闭环",A14<>""),(C14+C15)/2,"") | N14: =IF(M14<>"","±","") | O14: =IF(M14<>"",ABS((B14+B15)/2),"") | Q14: =IF(M14<>"",P14*2,"") | R14: =IF(M14="","",M14+P14) | T14: =IF(S14="","",S14+P14) | U14: =IF(M14<>"",K14,"") | V14: =IF(AND(F14<>"封闭环",H14<>""),H14,"") | W14: =IF(V14<>"",T14-V14,"")
C15: =IF(A14="","",A14+B15) | J15: =IF(H14="","",H14+I15) | R15: =IF(M14="","",M14-P14) | T15: =IF(S14="","",S14-P14) | W15: =IF(V14<>"",T15-V14,"")
